Workbook

Sheet Customers
A1: Customer_ID | B1: Age | C1: Gender | D1: Region | E1: Occupation | F1: Marital_Status | G1: Annual_Income_EUR | H1: Tenure_Years | I1: Account_Open_Date | J1: Preferred_Channel | K1: Num_Products | L1: Checking_Balance_EUR | M1: Savings_Balance_EUR | N1: Monthly_Transactions | O1: Avg_Transaction_EUR | P1: Monthly_ATM_Withdrawals | Q1: Card_Limit_EUR | R1: Monthly_Card_Spend_EUR | S1: Mortgage_Balance_EUR | T1: Monthly_Mortgage_Payment_EUR | U1: Credit_Score | V1: Complaints_12M
A2: CL00001 | B2: 18 | C2: M | D2: Campania | E2: Employee | F2: Single | G2: 25900 | H2: 0 | I2: 46008 | J2: Online Banking | K2: 2 | L2: 5758.21 | M2: 3643.27 | N2: 21 | O2: 23.72 | P2: 2 | Q2: 0 | R2: 0 | S2: 0 | T2: 0 | U2: 598 | V2: 0
A3: CL00002 | B3: 34 | C3: M | D3: Veneto | E3: Employee | F3: Married | G3: 17200 | H3: 8 | I3: 43326 | J3: App | K3: 1 | L3: 807.12 | M3: 18365.11 | N3: 26 | O3: 24.13 | P3: 0 | Q3: 60000 | R3: 2383.65 | S3: 0 | T3: 0 | U3: 529 | V3: 0
A4: CL00003 | B4: 38 | C4: F | D4: Lombardia | E4: Self-employed | F4: Married | G4: 61200 | H4: 3 | I4: 44850 | J4: App | K4: 1 | L4: 3371.02 | M4: 12031.56 | N4: 34 | O4: 107.36 | P4: 4 | Q4: 13500 | R4: 3032.1 | S4: 0 | T4: 0 | U4: 644 | V4: 0
A5: CL00004 | B5: 60 | C5: F | D5: Puglia | E5: Employee | F5: Widowed | G5: 26100 | H5: 20 | I5: 38715 | J5: Branch | K5: 1 | L5: 1236.32 | M5: 16031.41 | N5: 18 | O5: 54.56 | P5: 6 | Q5: 3000 | R5: 989.63 | S5: 0 | T5: 0 | U5: 661 | V5: 1
A6: CL00005 | B6: 34 | C6: M | D6: Piemonte | E6: Business owner | F6: Married | G6: 90400 | H6: 3 | I6: 44941 | J6: App | K6: 1 | L6: 8268.48 | M6: 0 | N6: 45 | O6: 119.75 | P6: 2 | Q6: 0 | R6: 0 | S6: 249000 | T6: 1355 | U6: 655 | V6: 0
A7: CL00006 | B7: 33 | C7: F | D7: Marche | E7: Manual worker | F7: Married | G7: 25500 | H7: 7 | I7: 43552 | J7: App | K7: 1 | L7: 932.74 | M7: 0 | N7: 26 | O7: 33 | P7: 2 | Q7: 0 | R7: 0 | S7: 0 | T7: 0 | U7: 556 | V7: 0
A8: CL00007 | B8: 40 | C8: M | D8: Campania | E8: Self-employed | F8: Single | G8: 35300 | H8: 8 | I8: 43193 | J8: Branch | K8: 1 | L8: 4814.58 | M8: 25412.02 | N8: 24 | O8: 33.81 | P8: 7 | Q8: 6000 | R8: 3472.77 | S8: 0 | T8: 0 | U8: 611 | V8: 0
A9: CL00008 | B9: 51 | C9: M | D9: Campania | E9: Business owner | F9: Divorced | G9: 60200 | H9: 8 | I9: 43152 | J9: Phone | K9: 1 | L9: 4195.77 | M9: 0 | N9: 34 | O9: 36.06 | P9: 2 | Q9: 0 | R9: 0 | S9: 191000 | T9: 1122 | U9: 653 | V9: 0
A10: CL00009 | B10: 35 | C10: M | D10: Abruzzo | E10: Manual worker | F10: Divorced | G10: 18700 | H10: 8 | I10: 43036 | J10: App | K10: 2 | L10: 3543.25 | M10: 4344.98 | N10: 31 | O10: 37.3 | P10: 1 | Q10: 4500 | R10: 1848.95 | S10: 64000 | T10: 316 | U10: 636 | V10: 0
A11: CL00010 | B11: 42 | C11: F | D11: Piemonte | E11: Manual worker | F11: Divorced | G11: 20600 | H11: 8 | I11: 43029 | J11: Online Banking | K11: 2 | L11: 1420.04 | M11: 11463.31 | N11: 29 | O11: 35.63 | P11: 1 | Q11: 0 | R11: 0 | S11: 0 | T11: 0 | U11: 641 | V11: 2
A12: CL00011 | B12: 33 | C12: F | D12: Lombardia | E12: Teacher | F12: Married | G12: 27200 | H12: 2 | I12: 45315 | J12: Online Banking | K12: 2 | L12: 2148.99 | M12: 13164.51 | N12: 29 | O12: 42.36 | P12: 5 | Q12: 5000 | R12: 907.68 | S12: 54000 | T12: 278 | U12: 598 | V12: 1
A13: CL00012 | B13: 49 | C13: M | D13: Veneto | E13: Business owner | F13: Married | G13: 82900 | H13: 5 | I13: 44241 | J13: App | K13: 2 | L13: 3302.9 | M13: 60831.37 | N13: 43 | O13: 59.29 | P13: 0 | Q13: 12500 | R13: 834.11 | S13: 0 | T13: 0 | U13: 675 | V13: 0
... A326: CL00320 | B326: 51 | C326: F | D326: Liguria | E326: Manual worker | F326: Married | G326: 17400 | H326: 28 | I326: 35693 | J326: Online Banking | K326: 3 | L326: 1271.02 | M326: 0 | N326: 21 | O326: 61.46 | P326: 3 | Q326: 2000 | R326: 827.17 | S326: 0 | T326: 0 | U326: 682 | V326: 0
A327: CL00321 | B327: 51 | C327: M | D327: Sardegna | E327: Shopkeeper | F327: Married | H327: 15 | I327: 40599 | J327: App | K327: 6 | L327: 2011.14 | M327: 12379.47 | N327: 32 | O327: 73.22 | P327: 1 | Q327: 5000 | R327: 646.39 | S327: 100000 | T327: 601 | U327: 660 | V327: 0
A328: CL00322 | B328: 61 | C328: M | D328: Campania | E328: Employee | F328: Divorced | G328: 58600 | H328: 31 | I328: 34929 | J328: Online Banking | K328: 2 | L328: 3993.46 | M328: 99658.82 | N328: 43 | O328: 86.75 | P328: 3 | Q328: 0 | R328: 0 | S328: 247000 | T328: 1674 | U328: 654 | V328: 0
A329: CL00323 | B329: 34 | C329: F | D329: Lombardia | E329: Employee | F329: Married | G329: 27300 | H329: 7 | I329: 43566 | J329: App | K329: 3 | L329: -885.13 | M329: 12276.86 | N329: 17 | O329: 51.08 | P329: 0 | Q329: 5500 | R329: 1032.22 | S329: 120000 | T329: 775 | U329: 625 | V329: 0
A330: CL00324 | B330: 50 | C330: F | D330: Emilia-Romagna | E330: Employee | F330: Married | G330: 29000 | H330: 13 | I330: 41412 | J330: Online Banking | K330: 2 | L330: -1057.82 | M330: 14123.96 | N330: 30 | O330: 50.26 | P330: 6 | Q330: 5000 | R330: 974.87 | S330: 0 | T330: 0 | U330: 659 | V330: 0
A331: CL00325 | B331: 41 | C331: F | D331: Piemonte | E331: Manual worker | F331: Married | G331: 31500 | H331: 2 | I331: 45494 | J331: Online Banking | K331: 1 | L331: 3410.51 | M331: 0 | N331: 27 | O331: 50.32 | P331: 2 | Q331: 4000 | R331: 696.38 | S331: 0 | T331: 0 | U331: 638 | V331: 1
A332: CL00326 | B332: 39 | C332: F | D332: Puglia | E332: Manual worker | F332: Married | G332: 34900 | H332: 10 | I332: 42435 | J332: App | K332: 3 | L332: 1353.63 | M332: 35048.42 | N332: 25 | O332: 32.55 | P332: 1 | Q332: 3500 | R332: 258.68 | S332: 0 | T332: 0 | U332: 619 | V332: 1
A333: CL00327 | B333: 50 | C333: F | D333: Abruzzo | E333: Employee | F333: Married | G333: 29100 | H333: 20 | I333: 38968 | J333: App | K333: 4 | L333: 2893.47 | M333: 0 | N333: 25 | O333: 30.21 | P333: 1 | Q333: 4000 | R333: 138.62 | S333: 0 | T333: 0 | U333: 687 | V333: 0
A334: CL00328 | B334: 47 | C334: M | D334: Lazio | E334: Teacher | F334: Married | G334: 50800 | H334: 4 | I334: 44459 | J334: Phone | K334: 1 | L334: 6637.83 | M334: 11964.55 | N334: 29 | O334: 46.42 | P334: 4 | Q334: 12000 | R334: 339.45 | S334: 0 | T334: 0 | U334: 649 | V334: 1
A335: CL00329 | B335: 31 | C335: M | D335: Veneto | E335: Executive | F335: Single | G335: 94000 | H335: 5 | I335: 44095 | J335: App | K335: 1 | L335: 8052.1 | M335: 23930.35 | N335: 54 | O335: 43.37 | P335: 0 | Q335: 0 | R335: 0 | S335: 0 | T335: 0 | U335: 704 | V335: 0
A336: CL00330 | B336: 55 | C336: F | D336: Sardegna | E336: Manual worker | F336: Single | G336: 26100 | H336: 19 | I336: 39006 | J336: Branch | K336: 5 | L336: 1379 | M336: 9492.38 | N336: 17 | O336: 84.92 | P336: 4 | Q336: 3000 | R336: 1352.34 | S336: 0 | T336: 0 | U336: 635 | V336: 0
A337: CL00331 | B337: 49 | C337: M | D337: Lazio | E337: Manual worker | F337: Divorced | G337: 25500 | H337: 11 | I337: 42240 | J337: Online Banking | K337: 3 | L337: 1825.41 | M337: 13391.17 | N337: 28 | O337: 79.26 | P337: 5 | Q337: 2500 | R337: 742.45 | S337: 64000 | T337: 472 | U337: 583 | V337: 0
A338: CL00332 | B338: 57 | C338: M | D338: Lombardia | E338: Self-employed | F338: Married | G338: 73500 | H338: 13 | I338: 41493 | J338: Branch | K338: 2 | L338: 3647.27 | M338: 55919.85 | N338: 41 | O338: 69.64 | P338: 3 | Q338: 15000 | R338: 4683.93 | S338: 0 | T338: 0 | U338: 642 | V338: 1
A339: CL00333 | B339: 26 | C339: F | D339: Campania | E339: Unemployed | F339: Single | G339: 8800 | H339: 0 | I339: 45978 | J339: App | K339: 1 | L339: 554.04 | M339: 0 | N339: 48 | O339: 199 | P339: 0 | Q339: 0 | R339: 0 | S339: 0 | T339: 0 | U339: 657 | V339: 0
... A511: CL00505 | B511: 47 | C511: F | D511: Puglia | E511: Employee | F511: Single | G511: 27200 | H511: 21 | I511: 38319 | J511: Branch | K511: 3 | L511: 1895.12 | M511: 0 | N511: 28 | O511: 49.64 | P511: 2 | Q511: 6000 | R511: 1788.23 | S511: 0 | T511: 0 | U511: 644 | V511: 0
A512: CL00506 | B512: 44 | C512: F | D512: Lombardia | E512: Executive | F512: Divorced | G512: 88800 | H512: 5 | I512: 44381 | J512: App | K512: 3 | L512: 7433.02 | N512: 59 | O512: 44.22 | P512: 2 | Q512: 10500 | R512: 2460.45 | S512: 396000 | T512: 2449 | U512: 674 | V512: 1
A513: CL00507 | B513: 23 | C513: M | D513: Sardegna | E513: Retired | F513: Single | G513: 4700 | H513: 2 | I513: 45523 | J513: App | K513: 1 | L513: 603.31 | M513: 2101.95 | N513: 30 | O513: 39.73 | P513: 1 | Q513: 0 | R513: 0 | S513: 0 | T513: 0 | U513: 512 | V513: 0
A514: CL00508 | B514: 33 | C514: F | D514: Marche | E514: Manual worker | F514: Married | G514: 29700 | H514: 5 | I514: 44335 | J514: App | K514: 2 | L514: 3500.93 | M514: 19581.17 | N514: 35 | O514: 49.09 | P514: 2 | Q514: 6000 | R514: 80.7 | S514: 0 | T514: 0 | U514: 616 | V514: 0
A515: CL00509 | B515: 44 | C515: M | D515: Marche | E515: Employee | F515: Single | G515: 31800 | H515: 9 | I515: 42647 | J515: Online Banking | K515: 1 | L515: 1545.25 | M515: 0 | N515: 37 | O515: 45.03 | P515: 3 | Q515: 0 | R515: 0 | S515: 0 | T515: 0 | U515: 567 | V515: 1
A516: CL00510 | B516: 73 | C516: F | D516: Veneto | E516: Retired | F516: Married | G516: 28700 | H516: 5 | I516: 44162 | J516: Branch | K516: 3 | L516: 4140.01 | M516: 9548.4 | N516: 25 | O516: 84.65 | P516: 2 | Q516: 5500 | R516: 1330.93 | S516: 0 | T516: 0 | U516: 601 | V516: 0
A517: CL00511 | B517: 48 | C517: F | D517: Lazio | E517: Employee | F517: Married | G517: 19600 | H517: 28 | I517: 35906 | J517: Online Banking | K517: 5 | L517: 2265.44 | M517: 54829.29 | N517: 25 | O517: 43.09 | P517: 1 | Q517: 5000 | R517: 2230.35 | S517: 0 | T517: 0 | U517: 669 | V517: 0
A518: CL00512 | B518: 47 | C518: F | D518: Lombardia | E518: Employee | F518: Married | G518: 33500 | H518: 5 | I518: 44408 | J518: Branch | K518: 1 | L518: 962.15 | M518: 19435.98 | N518: 14 | O518: 39.34 | P518: 6 | Q518: 5000 | R518: 160.09 | S518: 162000 | T518: 837 | U518: 620 | V518: 0
A519: CL00513 | B519: 47 | C519: M | D519: Abruzzo | E519: Employee | F519: Married | G519: 25200 | H519: 7 | I519: 43433 | J519: Online Banking | K519: 1 | L519: 3330.14 | M519: 0 | N519: 23 | O519: 27.86 | P519: 3 | Q519: 3500 | R519: 1275.87 | S519: 0 | T519: 0 | U519: 635 | V519: 0
A520: CL00514 | B520: 29 | C520: F | D520: Sicilia | E520: Manual worker | F520: Married | G520: 19700 | H520: 7 | I520: 43507 | J520: App | K520: 1 | L520: 919.22 | M520: 17762.87 | N520: 19 | O520: 59.89 | P520: 1 | Q520: 0 | R520: 0 | S520: 0 | T520: 0 | U520: 1200 | V520: 2
A521: CL00515 | B521: 76 | C521: M | D521: Lombardia | E521: Retired | F521: Married | G521: 16700 | H521: 17 | I521: 40061 | J521: Branch | K521: 2 | L521: 2929.26 | M521: 38268.37 | N521: 16 | O521: 74.67 | P521: 2 | Q521: 0 | R521: 0 | S521: 0 | T521: 0 | U521: 623 | V521: 1
A522: CL00516 | B522: 37 | C522: M | D522: Abruzzo | E522: Employee | F522: Married | G522: 26000 | H522: 15 | I522: 40751 | J522: App | K522: 1 | L522: 2521.45 | M522: 0 | N522: 29 | O522: 48.34 | P522: 1 | Q522: 4500 | R522: 860.3 | S522: 124000 | T522: 855 | U522: 589 | V522: 1
A523: CL00517 | B523: 45 | C523: F | D523: Friuli-Venezia Giulia | E523: Self-employed | F523: Married | G523: 69100 | H523: 6 | I523: 43841 | J523: App | K523: 1 | L523: 2880.7 | M523: 28560.07 | N523: 45 | O523: 46.56 | P523: 0 | Q523: 7500 | R523: 2264.39 | S523: 255000 | T523: 1657 | U523: 585 | V523: 0
...

Sheet Data_Dictionary
A1: Data dictionary — Customers sheet
A2: Demographic and behavioural extract as of 2026-09-13 for 1,000 retail customers (synthetic data). The 'Expected values' column describes the plausible range according to the business rules: any value outside this range, or inconsistent with the other columns, is a possible outlier to be verified.
A4: Column | B4: Type | C4: Description | D4: Expected values / plausible range
A5: Customer_ID | B5: Text | C5: Unique customer identifier (CL + 5 digits). | D5: Unique; format CL00001
A6: Age | B6: Integer | C6: Customer age in completed years. | D6: 18 – 100
A7: Gender | B7: Categorical | C7: Gender as recorded in the master data. | D7: M, F
A8: Region | B8: Categorical | C8: Region of residence (Italy). | D8: One of the 20 Italian regions, standard spelling
A9: Occupation | B9: Categorical | C9: Declared occupation. | D9: Employee, Manual worker, Self-employed, Executive, Business owner, Shopkeeper, Teacher, Student, Retired, Unemployed
A10: Marital_Status | B10: Categorical | C10: Marital status. | D10: Single, Married, Divorced, Widowed
A11: Annual_Income_EUR | B11: Numeric | C11: Declared gross annual income, in euros. | D11: > 0; typically 4,000 – 200,000
A12: Tenure_Years | B12: Integer | C12: Years of relationship with the bank. | D12: 0 – 40 and ≤ Age − 18
A13: Account_Open_Date | B13: Date | C13: Opening date of the first account. | D13: Between 1980 and the extraction date (2026-09-13); consistent with Tenure_Years
A14: Preferred_Channel | B14: Categorical | C14: Main contact channel. | D14: Branch, App, Online Banking, Phone
A15: Num_Products | B15: Integer | C15: Number of active products (account, cards, mortgage, investments…). | D15: 1 – 6
... A26: Complaints_12M | B26: Integer | C26: Complaints filed in the last 12 months. | D26: 0 – 5

Sheet Statistics
A1: Descriptive statistics and thresholds for detecting univariate outliers
A2: Every cell is a formula linked to the Customers sheet and updates when we change the data. The statistics are computed on the raw data, sentinels and errors included: we compare mean and median, or the number of outliers before and after cleaning, to see how much a single anomalous value distorts the thresholds.
A3: Statistic | B3: Age | C3: Annual_Income_EUR | D3: Tenure_Years | E3: Num_Products | F3: Checking_Balance_EUR | G3: Savings_Balance_EUR | H3: Monthly_Transactions | I3: Avg_Transaction_EUR | J3: Monthly_ATM_Withdrawals | K3: Card_Limit_EUR | L3: Monthly_Card_Spend_EUR | M3: Mortgage_Balance_EUR | N3: Monthly_Mortgage_Payment_EUR | O3: Credit_Score | P3: Complaints_12M
A4: Column in the Customers sheet | B4: B | C4: G | D4: H | E4: K | F4: L | G4: M | H4: N | I4: O | J4: P | K4: Q | L4: R | M4: S | N4: T | O4: U | P4: V
A5: N numeric values | B5: =COUNT(Customers!$B$2:$B$1001) -> 1000 | C5: =COUNT(Customers!$G$2:$G$1001) -> 997 | D5: =COUNT(Customers!$H$2:$H$1001) -> 1000 | E5: =COUNT(Customers!$K$2:$K$1001) -> 1000 | F5: =COUNT(Customers!$L$2:$L$1001) -> 1000 | G5: =COUNT(Customers!$M$2:$M$1001) -> 997 | H5: =COUNT(Customers!$N$2:$N$1001) -> 1000 | I5: =COUNT(Customers!$O$2:$O$1001) -> 1000 | J5: =COUNT(Customers!$P$2:$P$1001) -> 1000 | K5: =COUNT(Customers!$Q$2:$Q$1001) -> 1000 | L5: =COUNT(Customers!$R$2:$R$1001) -> 1000 | M5: =COUNT(Customers!$S$2:$S$1001) -> 1000 | N5: =COUNT(Customers!$T$2:$T$1001) -> 1000 | O5: =COUNT(Customers!$U$2:$U$1001) -> 1000 | P5: =COUNT(Customers!$V$2:$V$1001) -> 1000
A6: Blank cells | B6: =COUNTBLANK(Customers!$B$2:$B$1001) -> 0 | C6: =COUNTBLANK(Customers!$G$2:$G$1001) -> 3 | D6: =COUNTBLANK(Customers!$H$2:$H$1001) -> 0 | E6: =COUNTBLANK(Customers!$K$2:$K$1001) -> 0 | F6: =COUNTBLANK(Customers!$L$2:$L$1001) -> 0 | G6: =COUNTBLANK(Customers!$M$2:$M$1001) -> 3 | H6: =COUNTBLANK(Customers!$N$2:$N$1001) -> 0 | I6: =COUNTBLANK(Customers!$O$2:$O$1001) -> 0 | J6: =COUNTBLANK(Customers!$P$2:$P$1001) -> 0 | K6: =COUNTBLANK(Customers!$Q$2:$Q$1001) -> 0 | L6: =COUNTBLANK(Customers!$R$2:$R$1001) -> 0 | M6: =COUNTBLANK(Customers!$S$2:$S$1001) -> 0 | N6: =COUNTBLANK(Customers!$T$2:$T$1001) -> 0 | O6: =COUNTBLANK(Customers!$U$2:$U$1001) -> 0 | P6: =COUNTBLANK(Customers!$V$2:$V$1001) -> 0
A7: Mean | B7: =AVERAGE(Customers!$B$2:$B$1001) -> 48.535 | C7: =AVERAGE(Customers!$G$2:$G$1001) -> 72479.411 | D7: =AVERAGE(Customers!$H$2:$H$1001) -> 10.762 | E7: =AVERAGE(Customers!$K$2:$K$1001) -> 2.292 | F7: =AVERAGE(Customers!$L$2:$L$1001) -> 3355.9521 | G7: =AVERAGE(Customers!$M$2:$M$1001) -> 35090.563 | H7: =AVERAGE(Customers!$N$2:$N$1001) -> 30.157 | I7: =AVERAGE(Customers!$O$2:$O$1001) -> 60.02013 | J7: =AVERAGE(Customers!$P$2:$P$1001) -> 2.996 | K7: =AVERAGE(Customers!$Q$2:$Q$1001) -> 4650.5 | L7: =AVERAGE(Customers!$R$2:$R$1001) -> 1316.4016 | M7: =AVERAGE(Customers!$S$2:$S$1001) -> 39135 | N7: =AVERAGE(Customers!$T$2:$T$1001) -> 236.239 | O7: =AVERAGE(Customers!$U$2:$U$1001) -> 662.65 | P7: =AVERAGE(Customers!$V$2:$V$1001) -> 0.264
A8: Median | B8: =MEDIAN(Customers!$B$2:$B$1001) -> 47 | C8: =MEDIAN(Customers!$G$2:$G$1001) -> 30000 | D8: =MEDIAN(Customers!$H$2:$H$1001) -> 9 | E8: =MEDIAN(Customers!$K$2:$K$1001) -> 2 | F8: =MEDIAN(Customers!$L$2:$L$1001) -> 2586.535 | G8: =MEDIAN(Customers!$M$2:$M$1001) -> 12208.93 | H8: =MEDIAN(Customers!$N$2:$N$1001) -> 27 | I8: =MEDIAN(Customers!$O$2:$O$1001) -> 52.34 | J8: =MEDIAN(Customers!$P$2:$P$1001) -> 3 | K8: =MEDIAN(Customers!$Q$2:$Q$1001) -> 4000 | L8: =MEDIAN(Customers!$R$2:$R$1001) -> 763.63 | M8: =MEDIAN(Customers!$S$2:$S$1001) -> 0 | N8: =MEDIAN(Customers!$T$2:$T$1001) -> 0 | O8: =MEDIAN(Customers!$U$2:$U$1001) -> 635 | P8: =MEDIAN(Customers!$V$2:$V$1001) -> 0
A9: Standard deviation | B9: =STDEV(Customers!$B$2:$B$1001) -> 44.967286 | C9: =STDEV(Customers!$G$2:$G$1001) -> 1015307.4 | D9: =STDEV(Customers!$H$2:$H$1001) -> 7.7556112 | E9: =STDEV(Customers!$K$2:$K$1001) -> 1.2042368 | F9: =STDEV(Customers!$L$2:$L$1001) -> 28382.348 | G9: =STDEV(Customers!$M$2:$M$1001) -> 176152.28 | H9: =STDEV(Customers!$N$2:$N$1001) -> 24.869919 | I9: =STDEV(Customers!$O$2:$O$1001) -> 31.47791 | J9: =STDEV(Customers!$P$2:$P$1001) -> 2.1855802 | K9: =STDEV(Customers!$Q$2:$Q$1001) -> 4700.9785 | L9: =STDEV(Customers!$R$2:$R$1001) -> 1663.5113 | M9: =STDEV(Customers!$S$2:$S$1001) -> 76448.448 | N9: =STDEV(Customers!$T$2:$T$1001) -> 470.06818 | O9: =STDEV(Customers!$U$2:$U$1001) -> 516.40549 | P9: =STDEV(Customers!$V$2:$V$1001) -> 0.67138272
A10: Minimum | B10: =MIN(Customers!$B$2:$B$1001) -> -3 | C10: =MIN(Customers!$G$2:$G$1001) -> -999 | D10: =MIN(Customers!$H$2:$H$1001) -> 0 | E10: =MIN(Customers!$K$2:$K$1001) -> 1 | F10: =MIN(Customers!$L$2:$L$1001) -> -850000 | G10: =MIN(Customers!$M$2:$M$1001) -> 0 | H10: =MIN(Customers!$N$2:$N$1001) -> 8 | I10: =MIN(Customers!$O$2:$O$1001) -> 14.58 | J10: =MIN(Customers!$P$2:$P$1001) -> -2 | K10: =MIN(Customers!$Q$2:$Q$1001) -> 0 | L10: =MIN(Customers!$R$2:$R$1001) -> 0 | M10: =MIN(Customers!$S$2:$S$1001) -> 0 | N10: =MIN(Customers!$T$2:$T$1001) -> 0 | O10: =MIN(Customers!$U$2:$U$1001) -> 150 | P10: =MIN(Customers!$V$2:$V$1001) -> 0
A11: Maximum | B11: =MAX(Customers!$B$2:$B$1001) -> 999 | C11: =MAX(Customers!$G$2:$G$1001) -> 32000000 | D11: =MAX(Customers!$H$2:$H$1001) -> 44 | E11: =MAX(Customers!$K$2:$K$1001) -> 6 | F11: =MAX(Customers!$L$2:$L$1001) -> 185000 | G11: =MAX(Customers!$M$2:$M$1001) -> 3100000 | H11: =MAX(Customers!$N$2:$N$1001) -> 615 | I11: =MAX(Customers!$O$2:$O$1001) -> 257.18 | J11: =MAX(Customers!$P$2:$P$1001) -> 12 | K11: =MAX(Customers!$Q$2:$Q$1001) -> 60000 | L11: =MAX(Customers!$R$2:$R$1001) -> 12500 | M11: =MAX(Customers!$S$2:$S$1001) -> 520000 | N11: =MAX(Customers!$T$2:$T$1001) -> 3800 | O11: =MAX(Customers!$U$2:$U$1001) -> 9999 | P11: =MAX(Customers!$V$2:$V$1001) -> 14
A12: Q1 (25th percentile) | B12: =QUARTILE(Customers!$B$2:$B$1001,1) -> 37 | C12: =QUARTILE(Customers!$G$2:$G$1001,1) -> 21000 | D12: =QUARTILE(Customers!$H$2:$H$1001,1) -> 5 | E12: =QUARTILE(Customers!$K$2:$K$1001,1) -> 1 | F12: =QUARTILE(Customers!$L$2:$L$1001,1) -> 1226.1375 | G12: =QUARTILE(Customers!$M$2:$M$1001,1) -> 0 | H12: =QUARTILE(Customers!$N$2:$N$1001,1) -> 21 | I12: =QUARTILE(Customers!$O$2:$O$1001,1) -> 39.365 | J12: =QUARTILE(Customers!$P$2:$P$1001,1) -> 1 | K12: =QUARTILE(Customers!$Q$2:$Q$1001,1) -> 0 | L12: =QUARTILE(Customers!$R$2:$R$1001,1) -> 0 | M12: =QUARTILE(Customers!$S$2:$S$1001,1) -> 0 | N12: =QUARTILE(Customers!$T$2:$T$1001,1) -> 0 | O12: =QUARTILE(Customers!$U$2:$U$1001,1) -> 595 | P12: =QUARTILE(Customers!$V$2:$V$1001,1) -> 0
A13: Q3 (75th percentile) | B13: =QUARTILE(Customers!$B$2:$B$1001,3) -> 56 | C13: =QUARTILE(Customers!$G$2:$G$1001,3) -> 44200 | D13: =QUARTILE(Customers!$H$2:$H$1001,3) -> 15 | E13: =QUARTILE(Customers!$K$2:$K$1001,3) -> 3 | F13: =QUARTILE(Customers!$L$2:$L$1001,3) -> 4978.71 | G13: =QUARTILE(Customers!$M$2:$M$1001,3) -> 30591.65 | H13: =QUARTILE(Customers!$N$2:$N$1001,3) -> 35 | I13: =QUARTILE(Customers!$O$2:$O$1001,3) -> 71.6725 | J13: =QUARTILE(Customers!$P$2:$P$1001,3) -> 4 | K13: =QUARTILE(Customers!$Q$2:$Q$1001,3) -> 7000 | L13: =QUARTILE(Customers!$R$2:$R$1001,3) -> 1967.355 | M13: =QUARTILE(Customers!$S$2:$S$1001,3) -> 56000 | N13: =QUARTILE(Customers!$T$2:$T$1001,3) -> 326 | O13: =QUARTILE(Customers!$U$2:$U$1001,3) -> 675 | P13: =QUARTILE(Customers!$V$2:$V$1001,3) -> 0
A14: IQR = Q3 − Q1 | B14: =B13-B12 -> 19 | C14: =C13-C12 -> 23200 | D14: =D13-D12 -> 10 | E14: =E13-E12 -> 2 | F14: =F13-F12 -> 3752.5725 | G14: =G13-G12 -> 30591.65 | H14: =H13-H12 -> 14 | I14: =I13-I12 -> 32.3075 | ... P14: =P13-P12 -> 0
A15: Lower fence = Q1 − 1.5·IQR | B15: =B12-1.5*B14 -> 8.5 | C15: =C12-1.5*C14 -> -13800 | D15: =D12-1.5*D14 -> -10 | E15: =E12-1.5*E14 -> -2 | F15: =F12-1.5*F14 -> -4402.7213 | G15: =G12-1.5*G14 -> -45887.475 | H15: =H12-1.5*H14 -> 0 | I15: =I12-1.5*I14 -> -9.09625 | ... P15: =P12-1.5*P14 -> 0
A16: Upper fence = Q3 + 1.5·IQR | B16: =B13+1.5*B14 -> 84.5 | C16: =C13+1.5*C14 -> 79000 | D16: =D13+1.5*D14 -> 30 | E16: =E13+1.5*E14 -> 6 | F16: =F13+1.5*F14 -> 10607.569 | G16: =G13+1.5*G14 -> 76479.125 | H16: =H13+1.5*H14 -> 56 | I16: =I13+1.5*I14 -> 120.13375 | ... P16: =P13+1.5*P14 -> 0
A17: N values below the lower fence | B17: =COUNTIF(Customers!$B$2:$B$1001,"<"&B15) -> 2 | C17: =COUNTIF(Customers!$G$2:$G$1001,"<"&C15) -> 0 | D17: =COUNTIF(Customers!$H$2:$H$1001,"<"&D15) -> 0 | E17: =COUNTIF(Customers!$K$2:$K$1001,"<"&E15) -> 0 | F17: =COUNTIF(Customers!$L$2:$L$1001,"<"&F15) -> 1 | G17: =COUNTIF(Customers!$M$2:$M$1001,"<"&G15) -> 0 | H17: =COUNTIF(Customers!$N$2:$N$1001,"<"&H15) -> 0 | I17: =COUNTIF(Customers!$O$2:$O$1001,"<"&I15) -> 0 | J17: =COUNTIF(Customers!$P$2:$P$1001,"<"&J15) -> 0 | K17: =COUNTIF(Customers!$Q$2:$Q$1001,"<"&K15) -> 0 | L17: =COUNTIF(Customers!$R$2:$R$1001,"<"&L15) -> 0 | M17: =COUNTIF(Customers!$S$2:$S$1001,"<"&M15) -> 0 | N17: =COUNTIF(Customers!$T$2:$T$1001,"<"&N15) -> 0 | O17: =COUNTIF(Customers!$U$2:$U$1001,"<"&O15) -> 8 | P17: =COUNTIF(Customers!$V$2:$V$1001,"<"&P15) -> 0
A18: N values above the upper fence | B18: =COUNTIF(Customers!$B$2:$B$1001,">"&B16) -> 6 | C18: =COUNTIF(Customers!$G$2:$G$1001,">"&C16) -> 74 | D18: =COUNTIF(Customers!$H$2:$H$1001,">"&D16) -> 18 | E18: =COUNTIF(Customers!$K$2:$K$1001,">"&E16) -> 0 | F18: =COUNTIF(Customers!$L$2:$L$1001,">"&F16) -> 62 | G18: =COUNTIF(Customers!$M$2:$M$1001,">"&G16) -> 55 | H18: =COUNTIF(Customers!$N$2:$N$1001,">"&H16) -> 31 | I18: =COUNTIF(Customers!$O$2:$O$1001,">"&I16) -> 49 | J18: =COUNTIF(Customers!$P$2:$P$1001,">"&J16) -> 16 | K18: =COUNTIF(Customers!$Q$2:$Q$1001,">"&K16) -> 2 | L18: =COUNTIF(Customers!$R$2:$R$1001,">"&L16) -> 42 | M18: =COUNTIF(Customers!$S$2:$S$1001,">"&M16) -> 100 | N18: =COUNTIF(Customers!$T$2:$T$1001,">"&N16) -> 100 | O18: =COUNTIF(Customers!$U$2:$U$1001,">"&O16) -> 8 | P18: =COUNTIF(Customers!$V$2:$V$1001,">"&P16) -> 220
A19: z = −3 threshold (mean − 3·SD) | B19: =B7-3*B9 -> -86.366859 | C19: =C7-3*C9 -> -2973442.7 | D19: =D7-3*D9 -> -12.504834 | E19: =E7-3*E9 -> -1.3207103 | F19: =F7-3*F9 -> -81791.091 | G19: =G7-3*G9 -> -493366.26 | H19: =H7-3*H9 -> -44.452757 | I19: =I7-3*I9 -> -34.413599 | ... P19: =P7-3*P9 -> -1.7501482
A20: z = +3 threshold (mean + 3·SD) | B20: =B7+3*B9 -> 183.43686 | C20: =C7+3*C9 -> 3118401.5 | D20: =D7+3*D9 -> 34.028834 | E20: =E7+3*E9 -> 5.9047103 | F20: =F7+3*F9 -> 88502.995 | G20: =G7+3*G9 -> 563547.39 | H20: =H7+3*H9 -> 104.76676 | I20: =I7+3*I9 -> 154.45386 | ... P20: =P7+3*P9 -> 2.2781482
A21: N values with |z| > 3 | B21: =COUNTIF(Customers!$B$2:$B$1001,"<"&B19)+COUNTIF(Customers!$B$2:$B$1001,">"&B20) -> 3 | C21: =COUNTIF(Customers!$G$2:$G$1001,"<"&C19)+COUNTIF(Customers!$G$2:$G$1001,">"&C20) -> 1 | D21: =COUNTIF(Customers!$H$2:$H$1001,"<"&D19)+COUNTIF(Customers!$H$2:$H$1001,">"&D20) -> 3 | E21: =COUNTIF(Customers!$K$2:$K$1001,"<"&E19)+COUNTIF(Customers!$K$2:$K$1001,">"&E20) -> 13 | F21: =COUNTIF(Customers!$L$2:$L$1001,"<"&F19)+COUNTIF(Customers!$L$2:$L$1001,">"&F20) -> 3 | G21: =COUNTIF(Customers!$M$2:$M$1001,"<"&G19)+COUNTIF(Customers!$M$2:$M$1001,">"&G20) -> 7 | H21: =COUNTIF(Customers!$N$2:$N$1001,"<"&H19)+COUNTIF(Customers!$N$2:$N$1001,">"&H20) -> 2 | I21: =COUNTIF(Customers!$O$2:$O$1001,"<"&I19)+COUNTIF(Customers!$O$2:$O$1001,">"&I20) -> 19 | J21: =COUNTIF(Customers!$P$2:$P$1001,"<"&J19)+COUNTIF(Customers!$P$2:$P$1001,">"&J20) -> 8 | K21: =COUNTIF(Customers!$Q$2:$Q$1001,"<"&K19)+COUNTIF(Customers!$Q$2:$Q$1001,">"&K20) -> 2 | L21: =COUNTIF(Customers!$R$2:$R$1001,"<"&L19)+COUNTIF(Customers!$R$2:$R$1001,">"&L20) -> 22 | M21: =COUNTIF(Customers!$S$2:$S$1001,"<"&M19)+COUNTIF(Customers!$S$2:$S$1001,">"&M20) -> 24 | N21: =COUNTIF(Customers!$T$2:$T$1001,"<"&N19)+COUNTIF(Customers!$T$2:$T$1001,">"&N20) -> 27 | O21: =COUNTIF(Customers!$U$2:$U$1001,"<"&O19)+COUNTIF(Customers!$U$2:$U$1001,">"&O20) -> 3 | P21: =COUNTIF(Customers!$V$2:$V$1001,"<"&P19)+COUNTIF(Customers!$V$2:$V$1001,">"&P20) -> 5

Sheet Checks
A1: Customer_ID | B1: Z_Income | C1: Income outside 1.5·IQR | D1: Plausible age | E1: Tenure vs age | F1: Card spend vs limit | G1: Mortgage vs payment | H1: Payment vs monthly income | I1: Plausible date | J1: Date vs tenure | K1: Duplicate ID | L1: Duplicate record | M1: Score within scale | N1: Positive income | O1: Missing values | P1: N flags | R1: Flag summary (rows of the Customers sheet)
A2: =Customers!A2 -> CL00001 | B2: =IF(Customers!G2="","",(Customers!G2-Statistics!$C$7)/Statistics!$C$9) -> -0.045877152 | C2: =IF(Customers!G2="","",IF(OR(Customers!G2<Statistics!$C$15,Customers!G2>Statistics!$C$16),"Outside 1.5·IQR","")) | D2: =IF(OR(Customers!B2<18,Customers!B2>100),"Implausible age","") | E2: =IF(Customers!H2>Customers!B2-18,"Tenure > age-18","") | F2: =IF(Customers!R2>Customers!Q2,"Card spend > limit","") | G2: =IF(OR(AND(Customers!S2>0,Customers!T2=0),AND(Customers!S2=0,Customers!T2>0)),"Mortgage/payment inconsistent","") | H2: =IF(AND(Customers!G2<>"",Customers!G2>0,Customers!T2>Customers!G2/12),"Payment > monthly income","") | I2: =IF(OR(Customers!I2>DATE(2026,9,13),YEAR(Customers!I2)<1980),"Implausible date","") | J2: =IF(Customers!I2>DATE(2026,9,13),"",IF(ABS(INT((DATE(2026,9,13)-Customers!I2)/365.25)-Customers!H2)>1,"Date/tenure inconsistent","")) | K2: =IF(COUNTIF(Customers!$A$2:$A$1001,Customers!A2)>1,"Duplicate ID","") | L2: =IF(COUNTIFS(Customers!$B$2:$B$1001,Customers!B2,Customers!$D$2:$D$1001,Customers!D2,Customers!$G$2:$G$1001,Customers!G2,Customers!$I$2:$I$1001,Customers!I2,Customers!$L$2:$L$1001,Customers!L2)>1,"Duplicate record","") | M2: =IF(OR(Customers!U2<300,Customers!U2>850),"Score out of range","") | N2: =IF(AND(Customers!G2<>"",Customers!G2<=0),"Income ≤ 0","") | O2: =IF(OR(Customers!G2="",Customers!M2=""),"Missing value","") | P2: =SUMPRODUCT(--(C2:O2<>"")) -> 0 | R2: Check | S2: N rows
A3: =Customers!A3 -> CL00002 | B3: =IF(Customers!G3="","",(Customers!G3-Statistics!$C$7)/Statistics!$C$9) -> -0.054445986 | C3: =IF(Customers!G3="","",IF(OR(Customers!G3<Statistics!$C$15,Customers!G3>Statistics!$C$16),"Outside 1.5·IQR","")) | D3: =IF(OR(Customers!B3<18,Customers!B3>100),"Implausible age","") | E3: =IF(Customers!H3>Customers!B3-18,"Tenure > age-18","") | F3: =IF(Customers!R3>Customers!Q3,"Card spend > limit","") | G3: =IF(OR(AND(Customers!S3>0,Customers!T3=0),AND(Customers!S3=0,Customers!T3>0)),"Mortgage/payment inconsistent","") | H3: =IF(AND(Customers!G3<>"",Customers!G3>0,Customers!T3>Customers!G3/12),"Payment > monthly income","") | I3: =IF(OR(Customers!I3>DATE(2026,9,13),YEAR(Customers!I3)<1980),"Implausible date","") | J3: =IF(Customers!I3>DATE(2026,9,13),"",IF(ABS(INT((DATE(2026,9,13)-Customers!I3)/365.25)-Customers!H3)>1,"Date/tenure inconsistent","")) | K3: =IF(COUNTIF(Customers!$A$2:$A$1001,Customers!A3)>1,"Duplicate ID","") | L3: =IF(COUNTIFS(Customers!$B$2:$B$1001,Customers!B3,Customers!$D$2:$D$1001,Customers!D3,Customers!$G$2:$G$1001,Customers!G3,Customers!$I$2:$I$1001,Customers!I3,Customers!$L$2:$L$1001,Customers!L3)>1,"Duplicate record","") | M3: =IF(OR(Customers!U3<300,Customers!U3>850),"Score out of range","") | N3: =IF(AND(Customers!G3<>"",Customers!G3<=0),"Income ≤ 0","") | O3: =IF(OR(Customers!G3="",Customers!M3=""),"Missing value","") | P3: =SUMPRODUCT(--(C3:O3<>"")) -> 0 | R3: |Z_Income| > 3 | S3: =COUNTIF(B$2:B$1001,">3")+COUNTIF(B$2:B$1001,"<-3") -> 1
A4: =Customers!A4 -> CL00003 | B4: =IF(Customers!G4="","",(Customers!G4-Statistics!$C$7)/Statistics!$C$9) -> -0.011109356 | C4: =IF(Customers!G4="","",IF(OR(Customers!G4<Statistics!$C$15,Customers!G4>Statistics!$C$16),"Outside 1.5·IQR","")) | D4: =IF(OR(Customers!B4<18,Customers!B4>100),"Implausible age","") | E4: =IF(Customers!H4>Customers!B4-18,"Tenure > age-18","") | F4: =IF(Customers!R4>Customers!Q4,"Card spend > limit","") | G4: =IF(OR(AND(Customers!S4>0,Customers!T4=0),AND(Customers!S4=0,Customers!T4>0)),"Mortgage/payment inconsistent","") | H4: =IF(AND(Customers!G4<>"",Customers!G4>0,Customers!T4>Customers!G4/12),"Payment > monthly income","") | I4: =IF(OR(Customers!I4>DATE(2026,9,13),YEAR(Customers!I4)<1980),"Implausible date","") | J4: =IF(Customers!I4>DATE(2026,9,13),"",IF(ABS(INT((DATE(2026,9,13)-Customers!I4)/365.25)-Customers!H4)>1,"Date/tenure inconsistent","")) | K4: =IF(COUNTIF(Customers!$A$2:$A$1001,Customers!A4)>1,"Duplicate ID","") | L4: =IF(COUNTIFS(Customers!$B$2:$B$1001,Customers!B4,Customers!$D$2:$D$1001,Customers!D4,Customers!$G$2:$G$1001,Customers!G4,Customers!$I$2:$I$1001,Customers!I4,Customers!$L$2:$L$1001,Customers!L4)>1,"Duplicate record","") | M4: =IF(OR(Customers!U4<300,Customers!U4>850),"Score out of range","") | N4: =IF(AND(Customers!G4<>"",Customers!G4<=0),"Income ≤ 0","") | O4: =IF(OR(Customers!G4="",Customers!M4=""),"Missing value","") | P4: =SUMPRODUCT(--(C4:O4<>"")) -> 0 | R4: Income outside 1.5·IQR | S4: =SUMPRODUCT(--(C$2:C$1001<>"")) -> 74
A5: =Customers!A5 -> CL00004 | B5: =IF(Customers!G5="","",(Customers!G5-Statistics!$C$7)/Statistics!$C$9) -> -0.045680168 | C5: =IF(Customers!G5="","",IF(OR(Customers!G5<Statistics!$C$15,Customers!G5>Statistics!$C$16),"Outside 1.5·IQR","")) | D5: =IF(OR(Customers!B5<18,Customers!B5>100),"Implausible age","") | E5: =IF(Customers!H5>Customers!B5-18,"Tenure > age-18","") | F5: =IF(Customers!R5>Customers!Q5,"Card spend > limit","") | G5: =IF(OR(AND(Customers!S5>0,Customers!T5=0),AND(Customers!S5=0,Customers!T5>0)),"Mortgage/payment inconsistent","") | H5: =IF(AND(Customers!G5<>"",Customers!G5>0,Customers!T5>Customers!G5/12),"Payment > monthly income","") | I5: =IF(OR(Customers!I5>DATE(2026,9,13),YEAR(Customers!I5)<1980),"Implausible date","") | J5: =IF(Customers!I5>DATE(2026,9,13),"",IF(ABS(INT((DATE(2026,9,13)-Customers!I5)/365.25)-Customers!H5)>1,"Date/tenure inconsistent","")) | K5: =IF(COUNTIF(Customers!$A$2:$A$1001,Customers!A5)>1,"Duplicate ID","") | L5: =IF(COUNTIFS(Customers!$B$2:$B$1001,Customers!B5,Customers!$D$2:$D$1001,Customers!D5,Customers!$G$2:$G$1001,Customers!G5,Customers!$I$2:$I$1001,Customers!I5,Customers!$L$2:$L$1001,Customers!L5)>1,"Duplicate record","") | M5: =IF(OR(Customers!U5<300,Customers!U5>850),"Score out of range","") | N5: =IF(AND(Customers!G5<>"",Customers!G5<=0),"Income ≤ 0","") | O5: =IF(OR(Customers!G5="",Customers!M5=""),"Missing value","") | P5: =SUMPRODUCT(--(C5:O5<>"")) -> 0 | R5: Plausible age | S5: =SUMPRODUCT(--(D$2:D$1001<>"")) -> 5
A6: =Customers!A6 -> CL00005 | B6: =IF(Customers!G6="","",(Customers!G6-Statistics!$C$7)/Statistics!$C$9) -> 0.017650407 | C6: =IF(Customers!G6="","",IF(OR(Customers!G6<Statistics!$C$15,Customers!G6>Statistics!$C$16),"Outside 1.5·IQR","")) -> Outside 1.5·IQR | D6: =IF(OR(Customers!B6<18,Customers!B6>100),"Implausible age","") | E6: =IF(Customers!H6>Customers!B6-18,"Tenure > age-18","") | F6: =IF(Customers!R6>Customers!Q6,"Card spend > limit","") | G6: =IF(OR(AND(Customers!S6>0,Customers!T6=0),AND(Customers!S6=0,Customers!T6>0)),"Mortgage/payment inconsistent","") | H6: =IF(AND(Customers!G6<>"",Customers!G6>0,Customers!T6>Customers!G6/12),"Payment > monthly income","") | I6: =IF(OR(Customers!I6>DATE(2026,9,13),YEAR(Customers!I6)<1980),"Implausible date","") | J6: =IF(Customers!I6>DATE(2026,9,13),"",IF(ABS(INT((DATE(2026,9,13)-Customers!I6)/365.25)-Customers!H6)>1,"Date/tenure inconsistent","")) | K6: =IF(COUNTIF(Customers!$A$2:$A$1001,Customers!A6)>1,"Duplicate ID","") | L6: =IF(COUNTIFS(Customers!$B$2:$B$1001,Customers!B6,Customers!$D$2:$D$1001,Customers!D6,Customers!$G$2:$G$1001,Customers!G6,Customers!$I$2:$I$1001,Customers!I6,Customers!$L$2:$L$1001,Customers!L6)>1,"Duplicate record","") | M6: =IF(OR(Customers!U6<300,Customers!U6>850),"Score out of range","") | N6: =IF(AND(Customers!G6<>"",Customers!G6<=0),"Income ≤ 0","") | O6: =IF(OR(Customers!G6="",Customers!M6=""),"Missing value","") | P6: =SUMPRODUCT(--(C6:O6<>"")) -> 1 | R6: Tenure vs age | S6: =SUMPRODUCT(--(E$2:E$1001<>"")) -> 5
A7: =Customers!A7 -> CL00006 | B7: =IF(Customers!G7="","",(Customers!G7-Statistics!$C$7)/Statistics!$C$9) -> -0.046271122 | C7: =IF(Customers!G7="","",IF(OR(Customers!G7<Statistics!$C$15,Customers!G7>Statistics!$C$16),"Outside 1.5·IQR","")) | D7: =IF(OR(Customers!B7<18,Customers!B7>100),"Implausible age","") | E7: =IF(Customers!H7>Customers!B7-18,"Tenure > age-18","") | F7: =IF(Customers!R7>Customers!Q7,"Card spend > limit","") | G7: =IF(OR(AND(Customers!S7>0,Customers!T7=0),AND(Customers!S7=0,Customers!T7>0)),"Mortgage/payment inconsistent","") | H7: =IF(AND(Customers!G7<>"",Customers!G7>0,Customers!T7>Customers!G7/12),"Payment > monthly income","") | I7: =IF(OR(Customers!I7>DATE(2026,9,13),YEAR(Customers!I7)<1980),"Implausible date","") | J7: =IF(Customers!I7>DATE(2026,9,13),"",IF(ABS(INT((DATE(2026,9,13)-Customers!I7)/365.25)-Customers!H7)>1,"Date/tenure inconsistent","")) | K7: =IF(COUNTIF(Customers!$A$2:$A$1001,Customers!A7)>1,"Duplicate ID","") | L7: =IF(COUNTIFS(Customers!$B$2:$B$1001,Customers!B7,Customers!$D$2:$D$1001,Customers!D7,Customers!$G$2:$G$1001,Customers!G7,Customers!$I$2:$I$1001,Customers!I7,Customers!$L$2:$L$1001,Customers!L7)>1,"Duplicate record","") | M7: =IF(OR(Customers!U7<300,Customers!U7>850),"Score out of range","") | N7: =IF(AND(Customers!G7<>"",Customers!G7<=0),"Income ≤ 0","") | O7: =IF(OR(Customers!G7="",Customers!M7=""),"Missing value","") | P7: =SUMPRODUCT(--(C7:O7<>"")) -> 0 | R7: Card spend vs limit | S7: =SUMPRODUCT(--(F$2:F$1001<>"")) -> 3
A8: =Customers!A8 -> CL00007 | B8: =IF(Customers!G8="","",(Customers!G8-Statistics!$C$7)/Statistics!$C$9) -> -0.036618872 | C8: =IF(Customers!G8="","",IF(OR(Customers!G8<Statistics!$C$15,Customers!G8>Statistics!$C$16),"Outside 1.5·IQR","")) | D8: =IF(OR(Customers!B8<18,Customers!B8>100),"Implausible age","") | E8: =IF(Customers!H8>Customers!B8-18,"Tenure > age-18","") | F8: =IF(Customers!R8>Customers!Q8,"Card spend > limit","") | G8: =IF(OR(AND(Customers!S8>0,Customers!T8=0),AND(Customers!S8=0,Customers!T8>0)),"Mortgage/payment inconsistent","") | H8: =IF(AND(Customers!G8<>"",Customers!G8>0,Customers!T8>Customers!G8/12),"Payment > monthly income","") | I8: =IF(OR(Customers!I8>DATE(2026,9,13),YEAR(Customers!I8)<1980),"Implausible date","") | J8: =IF(Customers!I8>DATE(2026,9,13),"",IF(ABS(INT((DATE(2026,9,13)-Customers!I8)/365.25)-Customers!H8)>1,"Date/tenure inconsistent","")) | K8: =IF(COUNTIF(Customers!$A$2:$A$1001,Customers!A8)>1,"Duplicate ID","") | L8: =IF(COUNTIFS(Customers!$B$2:$B$1001,Customers!B8,Customers!$D$2:$D$1001,Customers!D8,Customers!$G$2:$G$1001,Customers!G8,Customers!$I$2:$I$1001,Customers!I8,Customers!$L$2:$L$1001,Customers!L8)>1,"Duplicate record","") | M8: =IF(OR(Customers!U8<300,Customers!U8>850),"Score out of range","") | N8: =IF(AND(Customers!G8<>"",Customers!G8<=0),"Income ≤ 0","") | O8: =IF(OR(Customers!G8="",Customers!M8=""),"Missing value","") | P8: =SUMPRODUCT(--(C8:O8<>"")) -> 0 | R8: Mortgage vs payment | S8: =SUMPRODUCT(--(G$2:G$1001<>"")) -> 4
A9: =Customers!A9 -> CL00008 | B9: =IF(Customers!G9="","",(Customers!G9-Statistics!$C$7)/Statistics!$C$9) -> -0.01209428 | C9: =IF(Customers!G9="","",IF(OR(Customers!G9<Statistics!$C$15,Customers!G9>Statistics!$C$16),"Outside 1.5·IQR","")) | D9: =IF(OR(Customers!B9<18,Customers!B9>100),"Implausible age","") | E9: =IF(Customers!H9>Customers!B9-18,"Tenure > age-18","") | F9: =IF(Customers!R9>Customers!Q9,"Card spend > limit","") | G9: =IF(OR(AND(Customers!S9>0,Customers!T9=0),AND(Customers!S9=0,Customers!T9>0)),"Mortgage/payment inconsistent","") | H9: =IF(AND(Customers!G9<>"",Customers!G9>0,Customers!T9>Customers!G9/12),"Payment > monthly income","") | I9: =IF(OR(Customers!I9>DATE(2026,9,13),YEAR(Customers!I9)<1980),"Implausible date","") | J9: =IF(Customers!I9>DATE(2026,9,13),"",IF(ABS(INT((DATE(2026,9,13)-Customers!I9)/365.25)-Customers!H9)>1,"Date/tenure inconsistent","")) | K9: =IF(COUNTIF(Customers!$A$2:$A$1001,Customers!A9)>1,"Duplicate ID","") | L9: =IF(COUNTIFS(Customers!$B$2:$B$1001,Customers!B9,Customers!$D$2:$D$1001,Customers!D9,Customers!$G$2:$G$1001,Customers!G9,Customers!$I$2:$I$1001,Customers!I9,Customers!$L$2:$L$1001,Customers!L9)>1,"Duplicate record","") | M9: =IF(OR(Customers!U9<300,Customers!U9>850),"Score out of range","") | N9: =IF(AND(Customers!G9<>"",Customers!G9<=0),"Income ≤ 0","") | O9: =IF(OR(Customers!G9="",Customers!M9=""),"Missing value","") | P9: =SUMPRODUCT(--(C9:O9<>"")) -> 0 | R9: Payment vs monthly income | S9: =SUMPRODUCT(--(H$2:H$1001<>"")) -> 3
A10: =Customers!A10 -> CL00009 | B10: =IF(Customers!G10="","",(Customers!G10-Statistics!$C$7)/Statistics!$C$9) -> -0.052968601 | C10: =IF(Customers!G10="","",IF(OR(Customers!G10<Statistics!$C$15,Customers!G10>Statistics!$C$16),"Outside 1.5·IQR","")) | D10: =IF(OR(Customers!B10<18,Customers!B10>100),"Implausible age","") | E10: =IF(Customers!H10>Customers!B10-18,"Tenure > age-18","") | F10: =IF(Customers!R10>Customers!Q10,"Card spend > limit","") | G10: =IF(OR(AND(Customers!S10>0,Customers!T10=0),AND(Customers!S10=0,Customers!T10>0)),"Mortgage/payment inconsistent","") | H10: =IF(AND(Customers!G10<>"",Customers!G10>0,Customers!T10>Customers!G10/12),"Payment > monthly income","") | I10: =IF(OR(Customers!I10>DATE(2026,9,13),YEAR(Customers!I10)<1980),"Implausible date","") | J10: =IF(Customers!I10>DATE(2026,9,13),"",IF(ABS(INT((DATE(2026,9,13)-Customers!I10)/365.25)-Customers!H10)>1,"Date/tenure inconsistent","")) | K10: =IF(COUNTIF(Customers!$A$2:$A$1001,Customers!A10)>1,"Duplicate ID","") | L10: =IF(COUNTIFS(Customers!$B$2:$B$1001,Customers!B10,Customers!$D$2:$D$1001,Customers!D10,Customers!$G$2:$G$1001,Customers!G10,Customers!$I$2:$I$1001,Customers!I10,Customers!$L$2:$L$1001,Customers!L10)>1,"Duplicate record","") | M10: =IF(OR(Customers!U10<300,Customers!U10>850),"Score out of range","") | N10: =IF(AND(Customers!G10<>"",Customers!G10<=0),"Income ≤ 0","") | O10: =IF(OR(Customers!G10="",Customers!M10=""),"Missing value","") | P10: =SUMPRODUCT(--(C10:O10<>"")) -> 0 | R10: Plausible date | S10: =SUMPRODUCT(--(I$2:I$1001<>"")) -> 4
A11: =Customers!A11 -> CL00010 | B11: =IF(Customers!G11="","",(Customers!G11-Statistics!$C$7)/Statistics!$C$9) -> -0.051097246 | C11: =IF(Customers!G11="","",IF(OR(Customers!G11<Statistics!$C$15,Customers!G11>Statistics!$C$16),"Outside 1.5·IQR","")) | D11: =IF(OR(Customers!B11<18,Customers!B11>100),"Implausible age","") | E11: =IF(Customers!H11>Customers!B11-18,"Tenure > age-18","") | F11: =IF(Customers!R11>Customers!Q11,"Card spend > limit","") | G11: =IF(OR(AND(Customers!S11>0,Customers!T11=0),AND(Customers!S11=0,Customers!T11>0)),"Mortgage/payment inconsistent","") | H11: =IF(AND(Customers!G11<>"",Customers!G11>0,Customers!T11>Customers!G11/12),"Payment > monthly income","") | I11: =IF(OR(Customers!I11>DATE(2026,9,13),YEAR(Customers!I11)<1980),"Implausible date","") | J11: =IF(Customers!I11>DATE(2026,9,13),"",IF(ABS(INT((DATE(2026,9,13)-Customers!I11)/365.25)-Customers!H11)>1,"Date/tenure inconsistent","")) | K11: =IF(COUNTIF(Customers!$A$2:$A$1001,Customers!A11)>1,"Duplicate ID","") | L11: =IF(COUNTIFS(Customers!$B$2:$B$1001,Customers!B11,Customers!$D$2:$D$1001,Customers!D11,Customers!$G$2:$G$1001,Customers!G11,Customers!$I$2:$I$1001,Customers!I11,Customers!$L$2:$L$1001,Customers!L11)>1,"Duplicate record","") | M11: =IF(OR(Customers!U11<300,Customers!U11>850),"Score out of range","") | N11: =IF(AND(Customers!G11<>"",Customers!G11<=0),"Income ≤ 0","") | O11: =IF(OR(Customers!G11="",Customers!M11=""),"Missing value","") | P11: =SUMPRODUCT(--(C11:O11<>"")) -> 0 | R11: Date vs tenure | S11: =SUMPRODUCT(--(J$2:J$1001<>"")) -> 4
A12: =Customers!A12 -> CL00011 | B12: =IF(Customers!G12="","",(Customers!G12-Statistics!$C$7)/Statistics!$C$9) -> -0.044596752 | C12: =IF(Customers!G12="","",IF(OR(Customers!G12<Statistics!$C$15,Customers!G12>Statistics!$C$16),"Outside 1.5·IQR","")) | D12: =IF(OR(Customers!B12<18,Customers!B12>100),"Implausible age","") | E12: =IF(Customers!H12>Customers!B12-18,"Tenure > age-18","") | F12: =IF(Customers!R12>Customers!Q12,"Card spend > limit","") | G12: =IF(OR(AND(Customers!S12>0,Customers!T12=0),AND(Customers!S12=0,Customers!T12>0)),"Mortgage/payment inconsistent","") | H12: =IF(AND(Customers!G12<>"",Customers!G12>0,Customers!T12>Customers!G12/12),"Payment > monthly income","") | I12: =IF(OR(Customers!I12>DATE(2026,9,13),YEAR(Customers!I12)<1980),"Implausible date","") | J12: =IF(Customers!I12>DATE(2026,9,13),"",IF(ABS(INT((DATE(2026,9,13)-Customers!I12)/365.25)-Customers!H12)>1,"Date/tenure inconsistent","")) | K12: =IF(COUNTIF(Customers!$A$2:$A$1001,Customers!A12)>1,"Duplicate ID","") | L12: =IF(COUNTIFS(Customers!$B$2:$B$1001,Customers!B12,Customers!$D$2:$D$1001,Customers!D12,Customers!$G$2:$G$1001,Customers!G12,Customers!$I$2:$I$1001,Customers!I12,Customers!$L$2:$L$1001,Customers!L12)>1,"Duplicate record","") | M12: =IF(OR(Customers!U12<300,Customers!U12>850),"Score out of range","") | N12: =IF(AND(Customers!G12<>"",Customers!G12<=0),"Income ≤ 0","") | O12: =IF(OR(Customers!G12="",Customers!M12=""),"Missing value","") | P12: =SUMPRODUCT(--(C12:O12<>"")) -> 0 | R12: Duplicate ID | S12: =SUMPRODUCT(--(K$2:K$1001<>"")) -> 6
A13: =Customers!A13 -> CL00012 | B13: =IF(Customers!G13="","",(Customers!G13-Statistics!$C$7)/Statistics!$C$9) -> 0.010263482 | C13: =IF(Customers!G13="","",IF(OR(Customers!G13<Statistics!$C$15,Customers!G13>Statistics!$C$16),"Outside 1.5·IQR","")) -> Outside 1.5·IQR | D13: =IF(OR(Customers!B13<18,Customers!B13>100),"Implausible age","") | E13: =IF(Customers!H13>Customers!B13-18,"Tenure > age-18","") | F13: =IF(Customers!R13>Customers!Q13,"Card spend > limit","") | G13: =IF(OR(AND(Customers!S13>0,Customers!T13=0),AND(Customers!S13=0,Customers!T13>0)),"Mortgage/payment inconsistent","") | H13: =IF(AND(Customers!G13<>"",Customers!G13>0,Customers!T13>Customers!G13/12),"Payment > monthly income","") | I13: =IF(OR(Customers!I13>DATE(2026,9,13),YEAR(Customers!I13)<1980),"Implausible date","") | J13: =IF(Customers!I13>DATE(2026,9,13),"",IF(ABS(INT((DATE(2026,9,13)-Customers!I13)/365.25)-Customers!H13)>1,"Date/tenure inconsistent","")) | K13: =IF(COUNTIF(Customers!$A$2:$A$1001,Customers!A13)>1,"Duplicate ID","") | L13: =IF(COUNTIFS(Customers!$B$2:$B$1001,Customers!B13,Customers!$D$2:$D$1001,Customers!D13,Customers!$G$2:$G$1001,Customers!G13,Customers!$I$2:$I$1001,Customers!I13,Customers!$L$2:$L$1001,Customers!L13)>1,"Duplicate record","") | M13: =IF(OR(Customers!U13<300,Customers!U13>850),"Score out of range","") | N13: =IF(AND(Customers!G13<>"",Customers!G13<=0),"Income ≤ 0","") | O13: =IF(OR(Customers!G13="",Customers!M13=""),"Missing value","") | P13: =SUMPRODUCT(--(C13:O13<>"")) -> 1 | R13: Duplicate record | S13: =SUMPRODUCT(--(L$2:L$1001<>"")) -> 12
A14: =Customers!A14 -> CL00013 | B14: =IF(Customers!G14="","",(Customers!G14-Statistics!$C$7)/Statistics!$C$9) -> -0.023223914 | C14: =IF(Customers!G14="","",IF(OR(Customers!G14<Statistics!$C$15,Customers!G14>Statistics!$C$16),"Outside 1.5·IQR","")) | D14: =IF(OR(Customers!B14<18,Customers!B14>100),"Implausible age","") | E14: =IF(Customers!H14>Customers!B14-18,"Tenure > age-18","") | F14: =IF(Customers!R14>Customers!Q14,"Card spend > limit","") | G14: =IF(OR(AND(Customers!S14>0,Customers!T14=0),AND(Customers!S14=0,Customers!T14>0)),"Mortgage/payment inconsistent","") | H14: =IF(AND(Customers!G14<>"",Customers!G14>0,Customers!T14>Customers!G14/12),"Payment > monthly income","") | I14: =IF(OR(Customers!I14>DATE(2026,9,13),YEAR(Customers!I14)<1980),"Implausible date","") | J14: =IF(Customers!I14>DATE(2026,9,13),"",IF(ABS(INT((DATE(2026,9,13)-Customers!I14)/365.25)-Customers!H14)>1,"Date/tenure inconsistent","")) | K14: =IF(COUNTIF(Customers!$A$2:$A$1001,Customers!A14)>1,"Duplicate ID","") | L14: =IF(COUNTIFS(Customers!$B$2:$B$1001,Customers!B14,Customers!$D$2:$D$1001,Customers!D14,Customers!$G$2:$G$1001,Customers!G14,Customers!$I$2:$I$1001,Customers!I14,Customers!$L$2:$L$1001,Customers!L14)>1,"Duplicate record","") | M14: =IF(OR(Customers!U14<300,Customers!U14>850),"Score out of range","") | N14: =IF(AND(Customers!G14<>"",Customers!G14<=0),"Income ≤ 0","") | O14: =IF(OR(Customers!G14="",Customers!M14=""),"Missing value","") | P14: =SUMPRODUCT(--(C14:O14<>"")) -> 0 | R14: Score within scale | S14: =SUMPRODUCT(--(M$2:M$1001<>"")) -> 5
A15: =Customers!A15 -> CL00014 | B15: =IF(Customers!G15="","",(Customers!G15-Statistics!$C$7)/Statistics!$C$9) -> -0.049225892 | C15: =IF(Customers!G15="","",IF(OR(Customers!G15<Statistics!$C$15,Customers!G15>Statistics!$C$16),"Outside 1.5·IQR","")) | D15: =IF(OR(Customers!B15<18,Customers!B15>100),"Implausible age","") | E15: =IF(Customers!H15>Customers!B15-18,"Tenure > age-18","") | F15: =IF(Customers!R15>Customers!Q15,"Card spend > limit","") | G15: =IF(OR(AND(Customers!S15>0,Customers!T15=0),AND(Customers!S15=0,Customers!T15>0)),"Mortgage/payment inconsistent","") | H15: =IF(AND(Customers!G15<>"",Customers!G15>0,Customers!T15>Customers!G15/12),"Payment > monthly income","") | I15: =IF(OR(Customers!I15>DATE(2026,9,13),YEAR(Customers!I15)<1980),"Implausible date","") | J15: =IF(Customers!I15>DATE(2026,9,13),"",IF(ABS(INT((DATE(2026,9,13)-Customers!I15)/365.25)-Customers!H15)>1,"Date/tenure inconsistent","")) | K15: =IF(COUNTIF(Customers!$A$2:$A$1001,Customers!A15)>1,"Duplicate ID","") | L15: =IF(COUNTIFS(Customers!$B$2:$B$1001,Customers!B15,Customers!$D$2:$D$1001,Customers!D15,Customers!$G$2:$G$1001,Customers!G15,Customers!$I$2:$I$1001,Customers!I15,Customers!$L$2:$L$1001,Customers!L15)>1,"Duplicate record","") | M15: =IF(OR(Customers!U15<300,Customers!U15>850),"Score out of range","") | N15: =IF(AND(Customers!G15<>"",Customers!G15<=0),"Income ≤ 0","") | O15: =IF(OR(Customers!G15="",Customers!M15=""),"Missing value","") | P15: =SUMPRODUCT(--(C15:O15<>"")) -> 0 | R15: Positive income | S15: =SUMPRODUCT(--(N$2:N$1001<>"")) -> 4
A16: =Customers!A16 -> CL00015 | B16: =IF(Customers!G16="","",(Customers!G16-Statistics!$C$7)/Statistics!$C$9) -> -0.049225892 | C16: =IF(Customers!G16="","",IF(OR(Customers!G16<Statistics!$C$15,Customers!G16>Statistics!$C$16),"Outside 1.5·IQR","")) | D16: =IF(OR(Customers!B16<18,Customers!B16>100),"Implausible age","") | E16: =IF(Customers!H16>Customers!B16-18,"Tenure > age-18","") | F16: =IF(Customers!R16>Customers!Q16,"Card spend > limit","") | G16: =IF(OR(AND(Customers!S16>0,Customers!T16=0),AND(Customers!S16=0,Customers!T16>0)),"Mortgage/payment inconsistent","") | H16: =IF(AND(Customers!G16<>"",Customers!G16>0,Customers!T16>Customers!G16/12),"Payment > monthly income","") | I16: =IF(OR(Customers!I16>DATE(2026,9,13),YEAR(Customers!I16)<1980),"Implausible date","") | J16: =IF(Customers!I16>DATE(2026,9,13),"",IF(ABS(INT((DATE(2026,9,13)-Customers!I16)/365.25)-Customers!H16)>1,"Date/tenure inconsistent","")) | K16: =IF(COUNTIF(Customers!$A$2:$A$1001,Customers!A16)>1,"Duplicate ID","") | L16: =IF(COUNTIFS(Customers!$B$2:$B$1001,Customers!B16,Customers!$D$2:$D$1001,Customers!D16,Customers!$G$2:$G$1001,Customers!G16,Customers!$I$2:$I$1001,Customers!I16,Customers!$L$2:$L$1001,Customers!L16)>1,"Duplicate record","") | M16: =IF(OR(Customers!U16<300,Customers!U16>850),"Score out of range","") | N16: =IF(AND(Customers!G16<>"",Customers!G16<=0),"Income ≤ 0","") | O16: =IF(OR(Customers!G16="",Customers!M16=""),"Missing value","") | P16: =SUMPRODUCT(--(C16:O16<>"")) -> 0 | R16: Missing values | S16: =SUMPRODUCT(--(O$2:O$1001<>"")) -> 6
A17: =Customers!A17 -> CL00016 | B17: =IF(Customers!G17="","",(Customers!G17-Statistics!$C$7)/Statistics!$C$9) -> -0.050900262 | C17: =IF(Customers!G17="","",IF(OR(Customers!G17<Statistics!$C$15,Customers!G17>Statistics!$C$16),"Outside 1.5·IQR","")) | D17: =IF(OR(Customers!B17<18,Customers!B17>100),"Implausible age","") | E17: =IF(Customers!H17>Customers!B17-18,"Tenure > age-18","") | F17: =IF(Customers!R17>Customers!Q17,"Card spend > limit","") | G17: =IF(OR(AND(Customers!S17>0,Customers!T17=0),AND(Customers!S17=0,Customers!T17>0)),"Mortgage/payment inconsistent","") | H17: =IF(AND(Customers!G17<>"",Customers!G17>0,Customers!T17>Customers!G17/12),"Payment > monthly income","") | I17: =IF(OR(Customers!I17>DATE(2026,9,13),YEAR(Customers!I17)<1980),"Implausible date","") | J17: =IF(Customers!I17>DATE(2026,9,13),"",IF(ABS(INT((DATE(2026,9,13)-Customers!I17)/365.25)-Customers!H17)>1,"Date/tenure inconsistent","")) | K17: =IF(COUNTIF(Customers!$A$2:$A$1001,Customers!A17)>1,"Duplicate ID","") | L17: =IF(COUNTIFS(Customers!$B$2:$B$1001,Customers!B17,Customers!$D$2:$D$1001,Customers!D17,Customers!$G$2:$G$1001,Customers!G17,Customers!$I$2:$I$1001,Customers!I17,Customers!$L$2:$L$1001,Customers!L17)>1,"Duplicate record","") | M17: =IF(OR(Customers!U17<300,Customers!U17>850),"Score out of range","") | N17: =IF(AND(Customers!G17<>"",Customers!G17<=0),"Income ≤ 0","") | O17: =IF(OR(Customers!G17="",Customers!M17=""),"Missing value","") | P17: =SUMPRODUCT(--(C17:O17<>"")) -> 0 | R17: Rows with at least one flag | S17: =COUNTIF(P$2:P$1001,">0") -> 124
A18: =Customers!A18 -> CL00017 | B18: =IF(Customers!G18="","",(Customers!G18-Statistics!$C$7)/Statistics!$C$9) -> -0.052377647 | C18: =IF(Customers!G18="","",IF(OR(Customers!G18<Statistics!$C$15,Customers!G18>Statistics!$C$16),"Outside 1.5·IQR","")) | D18: =IF(OR(Customers!B18<18,Customers!B18>100),"Implausible age","") | E18: =IF(Customers!H18>Customers!B18-18,"Tenure > age-18","") | F18: =IF(Customers!R18>Customers!Q18,"Card spend > limit","") | G18: =IF(OR(AND(Customers!S18>0,Customers!T18=0),AND(Customers!S18=0,Customers!T18>0)),"Mortgage/payment inconsistent","") | H18: =IF(AND(Customers!G18<>"",Customers!G18>0,Customers!T18>Customers!G18/12),"Payment > monthly income","") | I18: =IF(OR(Customers!I18>DATE(2026,9,13),YEAR(Customers!I18)<1980),"Implausible date","") | J18: =IF(Customers!I18>DATE(2026,9,13),"",IF(ABS(INT((DATE(2026,9,13)-Customers!I18)/365.25)-Customers!H18)>1,"Date/tenure inconsistent","")) | K18: =IF(COUNTIF(Customers!$A$2:$A$1001,Customers!A18)>1,"Duplicate ID","") | L18: =IF(COUNTIFS(Customers!$B$2:$B$1001,Customers!B18,Customers!$D$2:$D$1001,Customers!D18,Customers!$G$2:$G$1001,Customers!G18,Customers!$I$2:$I$1001,Customers!I18,Customers!$L$2:$L$1001,Customers!L18)>1,"Duplicate record","") | M18: =IF(OR(Customers!U18<300,Customers!U18>850),"Score out of range","") | N18: =IF(AND(Customers!G18<>"",Customers!G18<=0),"Income ≤ 0","") | O18: =IF(OR(Customers!G18="",Customers!M18=""),"Missing value","") | P18: =SUMPRODUCT(--(C18:O18<>"")) -> 0
A19: =Customers!A19 -> CL00018 | B19: =IF(Customers!G19="","",(Customers!G19-Statistics!$C$7)/Statistics!$C$9) -> -0.026671146 | C19: =IF(Customers!G19="","",IF(OR(Customers!G19<Statistics!$C$15,Customers!G19>Statistics!$C$16),"Outside 1.5·IQR","")) | D19: =IF(OR(Customers!B19<18,Customers!B19>100),"Implausible age","") | E19: =IF(Customers!H19>Customers!B19-18,"Tenure > age-18","") | F19: =IF(Customers!R19>Customers!Q19,"Card spend > limit","") | G19: =IF(OR(AND(Customers!S19>0,Customers!T19=0),AND(Customers!S19=0,Customers!T19>0)),"Mortgage/payment inconsistent","") | H19: =IF(AND(Customers!G19<>"",Customers!G19>0,Customers!T19>Customers!G19/12),"Payment > monthly income","") | I19: =IF(OR(Customers!I19>DATE(2026,9,13),YEAR(Customers!I19)<1980),"Implausible date","") | J19: =IF(Customers!I19>DATE(2026,9,13),"",IF(ABS(INT((DATE(2026,9,13)-Customers!I19)/365.25)-Customers!H19)>1,"Date/tenure inconsistent","")) | K19: =IF(COUNTIF(Customers!$A$2:$A$1001,Customers!A19)>1,"Duplicate ID","") | L19: =IF(COUNTIFS(Customers!$B$2:$B$1001,Customers!B19,Customers!$D$2:$D$1001,Customers!D19,Customers!$G$2:$G$1001,Customers!G19,Customers!$I$2:$I$1001,Customers!I19,Customers!$L$2:$L$1001,Customers!L19)>1,"Duplicate record","") | M19: =IF(OR(Customers!U19<300,Customers!U19>850),"Score out of range","") | N19: =IF(AND(Customers!G19<>"",Customers!G19<=0),"Income ≤ 0","") | O19: =IF(OR(Customers!G19="",Customers!M19=""),"Missing value","") | P19: =SUMPRODUCT(--(C19:O19<>"")) -> 0 | R19: The formulas use only basic functions (IF, COUNTIF, COUNTIFS, SUMPRODUCT) and refer to the thresholds in the Statistics sheet. The extraction date (2026-09-13) is fixed in the formulas with DATE(2026,9,13); in class we can replace it with TODAY().
A20: =Customers!A20 -> CL00019 | B20: =IF(Customers!G20="","",(Customers!G20-Statistics!$C$7)/Statistics!$C$9) -> -0.066363559 | C20: =IF(Customers!G20="","",IF(OR(Customers!G20<Statistics!$C$15,Customers!G20>Statistics!$C$16),"Outside 1.5·IQR","")) | D20: =IF(OR(Customers!B20<18,Customers!B20>100),"Implausible age","") | E20: =IF(Customers!H20>Customers!B20-18,"Tenure > age-18","") | F20: =IF(Customers!R20>Customers!Q20,"Card spend > limit","") | G20: =IF(OR(AND(Customers!S20>0,Customers!T20=0),AND(Customers!S20=0,Customers!T20>0)),"Mortgage/payment inconsistent","") | H20: =IF(AND(Customers!G20<>"",Customers!G20>0,Customers!T20>Customers!G20/12),"Payment > monthly income","") | I20: =IF(OR(Customers!I20>DATE(2026,9,13),YEAR(Customers!I20)<1980),"Implausible date","") | J20: =IF(Customers!I20>DATE(2026,9,13),"",IF(ABS(INT((DATE(2026,9,13)-Customers!I20)/365.25)-Customers!H20)>1,"Date/tenure inconsistent","")) | K20: =IF(COUNTIF(Customers!$A$2:$A$1001,Customers!A20)>1,"Duplicate ID","") | L20: =IF(COUNTIFS(Customers!$B$2:$B$1001,Customers!B20,Customers!$D$2:$D$1001,Customers!D20,Customers!$G$2:$G$1001,Customers!G20,Customers!$I$2:$I$1001,Customers!I20,Customers!$L$2:$L$1001,Customers!L20)>1,"Duplicate record","") | M20: =IF(OR(Customers!U20<300,Customers!U20>850),"Score out of range","") | N20: =IF(AND(Customers!G20<>"",Customers!G20<=0),"Income ≤ 0","") | O20: =IF(OR(Customers!G20="",Customers!M20=""),"Missing value","") | P20: =SUMPRODUCT(--(C20:O20<>"")) -> 0
A21: =Customers!A21 -> CL00020 | B21: =IF(Customers!G21="","",(Customers!G21-Statistics!$C$7)/Statistics!$C$9) -> -0.0026390148 | C21: =IF(Customers!G21="","",IF(OR(Customers!G21<Statistics!$C$15,Customers!G21>Statistics!$C$16),"Outside 1.5·IQR","")) | D21: =IF(OR(Customers!B21<18,Customers!B21>100),"Implausible age","") | E21: =IF(Customers!H21>Customers!B21-18,"Tenure > age-18","") | F21: =IF(Customers!R21>Customers!Q21,"Card spend > limit","") | G21: =IF(OR(AND(Customers!S21>0,Customers!T21=0),AND(Customers!S21=0,Customers!T21>0)),"Mortgage/payment inconsistent","") | H21: =IF(AND(Customers!G21<>"",Customers!G21>0,Customers!T21>Customers!G21/12),"Payment > monthly income","") | I21: =IF(OR(Customers!I21>DATE(2026,9,13),YEAR(Customers!I21)<1980),"Implausible date","") | J21: =IF(Customers!I21>DATE(2026,9,13),"",IF(ABS(INT((DATE(2026,9,13)-Customers!I21)/365.25)-Customers!H21)>1,"Date/tenure inconsistent","")) | K21: =IF(COUNTIF(Customers!$A$2:$A$1001,Customers!A21)>1,"Duplicate ID","") | L21: =IF(COUNTIFS(Customers!$B$2:$B$1001,Customers!B21,Customers!$D$2:$D$1001,Customers!D21,Customers!$G$2:$G$1001,Customers!G21,Customers!$I$2:$I$1001,Customers!I21,Customers!$L$2:$L$1001,Customers!L21)>1,"Duplicate record","") | M21: =IF(OR(Customers!U21<300,Customers!U21>850),"Score out of range","") | N21: =IF(AND(Customers!G21<>"",Customers!G21<=0),"Income ≤ 0","") | O21: =IF(OR(Customers!G21="",Customers!M21=""),"Missing value","") | P21: =SUMPRODUCT(--(C21:O21<>"")) -> 0
A22: =Customers!A22 -> CL00021 | B22: =IF(Customers!G22="","",(Customers!G22-Statistics!$C$7)/Statistics!$C$9) -> 0.0058313264 | C22: =IF(Customers!G22="","",IF(OR(Customers!G22<Statistics!$C$15,Customers!G22>Statistics!$C$16),"Outside 1.5·IQR","")) | D22: =IF(OR(Customers!B22<18,Customers!B22>100),"Implausible age","") | E22: =IF(Customers!H22>Customers!B22-18,"Tenure > age-18","") | F22: =IF(Customers!R22>Customers!Q22,"Card spend > limit","") | G22: =IF(OR(AND(Customers!S22>0,Customers!T22=0),AND(Customers!S22=0,Customers!T22>0)),"Mortgage/payment inconsistent","") | H22: =IF(AND(Customers!G22<>"",Customers!G22>0,Customers!T22>Customers!G22/12),"Payment > monthly income","") | I22: =IF(OR(Customers!I22>DATE(2026,9,13),YEAR(Customers!I22)<1980),"Implausible date","") | J22: =IF(Customers!I22>DATE(2026,9,13),"",IF(ABS(INT((DATE(2026,9,13)-Customers!I22)/365.25)-Customers!H22)>1,"Date/tenure inconsistent","")) | K22: =IF(COUNTIF(Customers!$A$2:$A$1001,Customers!A22)>1,"Duplicate ID","") | L22: =IF(COUNTIFS(Customers!$B$2:$B$1001,Customers!B22,Customers!$D$2:$D$1001,Customers!D22,Customers!$G$2:$G$1001,Customers!G22,Customers!$I$2:$I$1001,Customers!I22,Customers!$L$2:$L$1001,Customers!L22)>1,"Duplicate record","") | M22: =IF(OR(Customers!U22<300,Customers!U22>850),"Score out of range","") | N22: =IF(AND(Customers!G22<>"",Customers!G22<=0),"Income ≤ 0","") | O22: =IF(OR(Customers!G22="",Customers!M22=""),"Missing value","") | P22: =SUMPRODUCT(--(C22:O22<>"")) -> 0
A23: =Customers!A23 -> CL00022 | B23: =IF(Customers!G23="","",(Customers!G23-Statistics!$C$7)/Statistics!$C$9) -> -0.049422877 | C23: =IF(Customers!G23="","",IF(OR(Customers!G23<Statistics!$C$15,Customers!G23>Statistics!$C$16),"Outside 1.5·IQR","")) | D23: =IF(OR(Customers!B23<18,Customers!B23>100),"Implausible age","") | E23: =IF(Customers!H23>Customers!B23-18,"Tenure > age-18","") | F23: =IF(Customers!R23>Customers!Q23,"Card spend > limit","") | G23: =IF(OR(AND(Customers!S23>0,Customers!T23=0),AND(Customers!S23=0,Customers!T23>0)),"Mortgage/payment inconsistent","") | H23: =IF(AND(Customers!G23<>"",Customers!G23>0,Customers!T23>Customers!G23/12),"Payment > monthly income","") | I23: =IF(OR(Customers!I23>DATE(2026,9,13),YEAR(Customers!I23)<1980),"Implausible date","") | J23: =IF(Customers!I23>DATE(2026,9,13),"",IF(ABS(INT((DATE(2026,9,13)-Customers!I23)/365.25)-Customers!H23)>1,"Date/tenure inconsistent","")) | K23: =IF(COUNTIF(Customers!$A$2:$A$1001,Customers!A23)>1,"Duplicate ID","") | L23: =IF(COUNTIFS(Customers!$B$2:$B$1001,Customers!B23,Customers!$D$2:$D$1001,Customers!D23,Customers!$G$2:$G$1001,Customers!G23,Customers!$I$2:$I$1001,Customers!I23,Customers!$L$2:$L$1001,Customers!L23)>1,"Duplicate record","") | M23: =IF(OR(Customers!U23<300,Customers!U23>850),"Score out of range","") | N23: =IF(AND(Customers!G23<>"",Customers!G23<=0),"Income ≤ 0","") | O23: =IF(OR(Customers!G23="",Customers!M23=""),"Missing value","") | P23: =SUMPRODUCT(--(C23:O23<>"")) -> 0
