Workbook

Sheet Customers
A1: Customer_ID | B1: Age | C1: Gender | D1: Region | E1: Occupation | F1: Marital_Status | G1: Annual_Income_EUR | H1: Tenure_Years | I1: Account_Open_Date | J1: Preferred_Channel | K1: Num_Products | L1: Checking_Balance_EUR | M1: Savings_Balance_EUR | N1: Monthly_Transactions | O1: Avg_Transaction_EUR | P1: Monthly_ATM_Withdrawals | Q1: Card_Limit_EUR | R1: Monthly_Card_Spend_EUR | S1: Mortgage_Balance_EUR | T1: Monthly_Mortgage_Payment_EUR | U1: Credit_Score | V1: Complaints_12M
A2: CL00001 | B2: 57 | C2: F | D2: Marche | E2: Shopkeeper | F2: Married | G2: 30100 | H2: 4 | I2: 44721 | J2: Branch | K2: 2 | L2: 6763.27 | M2: 12100.75 | N2: 23 | O2: 36.84 | P2: 1 | S2: 93000 | T2: 603 | U2: 698
A3: CL00002 | B3: 60 | C3: M | D3: Abruzzo | E3: Business owner | F3: Married | G3: 117400 | H3: 13 | I3: 41314 | J3: Branch | K3: 3 | L3: 39402.14 | M3: 124631.07 | N3: 49 | O3: 65.95 | P3: 1 | Q3: 15000 | R3: 3434.25 | S3: 0 | T3: 0 | U3: 700
A4: CL00003 | B4: 42 | C4: F | D4: Molise | E4: Business owner | F4: Married | G4: 55600 | H4: 11 | I4: 41985 | J4: App | K4: 2 | L4: 2962.55 | M4: 70371.89 | N4: 33 | O4: 85.29 | P4: 1 | Q4: 11000 | R4: 3647.56 | U4: 749
A5: CL00004 | B5: 44 | C5: F | D5: Umbria | E5: Employee | F5: Single | G5: 30200 | H5: 13 | I5: 41353 | J5: App | K5: 2 | L5: 3055.07 | M5: 31571.98 | N5: 17 | O5: 30.81 | P5: 1 | Q5: 6000 | R5: 2242.95 | S5: 0 | T5: 0 | U5: 601 | V5: 0
A6: CL00005 | B6: 68 | C6: F | D6: Lombardia | E6: Retired | F6: Married | G6: 21800 | H6: 8 | I6: 43047 | J6: Phone | K6: 1 | L6: 1554.39 | M6: 27565.84 | N6: 24 | O6: 29.47 | P6: 4 | Q6: 5000 | R6: 1312.86 | U6: 568 | V6: 1
A7: CL00006 | B7: 56 | C7: F | D7: Sardegna | E7: Shopkeeper | F7: Married | G7: 42300 | H7: 25 | I7: 36979 | J7: Branch | K7: 2 | L7: 879.82 | N7: 34 | O7: 90.6 | P7: 4 | Q7: 4500 | R7: 1699.41 | S7: 0 | T7: 0 | U7: 618 | V7: 2
A8: CL00007 | B8: 67 | C8: F | D8: Lombardia | E8: Retired | F8: Married | G8: 28300 | H8: 2 | I8: 45278 | J8: Online Banking | K8: 2 | L8: 6616.63 | M8: 2752.06 | N8: 30 | O8: 76 | P8: 2 | Q8: 4000 | R8: 2532.26 | U8: 666
A9: CL00008 | B9: 43 | C9: M | D9: Calabria | E9: Teacher | F9: Married | G9: 28300 | H9: 10 | I9: 42273 | J9: App | K9: 4 | L9: -56.68 | M9: 28860.26 | N9: 23 | O9: 49.11 | P9: 3 | Q9: 3000 | R9: 363.95 | S9: 49000 | T9: 228 | U9: 544 | V9: 1
A10: CL00009 | B10: 25 | C10: M | D10: Campania | E10: Manual worker | G10: 17700 | H10: 3 | I10: 45141 | J10: Online Banking | K10: 2 | L10: 795.78 | M10: 8855.03 | N10: 25 | O10: 32.4 | P10: 3 | Q10: 0 | R10: 0 | S10: 0 | T10: 0 | U10: 536 | V10: 0
A11: CL00010 | B11: 36 | C11: M | D11: Piemonte | E11: Employee | F11: Single | G11: 32600 | H11: 7 | I11: 43377 | J11: App | K11: 1 | L11: -244.9 | M11: 0 | N11: 33 | O11: 68.04 | P11: 0 | Q11: 6000 | R11: 1052.22 | S11: 0 | T11: 0 | U11: 662
A12: CL00011 | B12: 60 | C12: M | D12: Veneto | E12: Business owner | F12: Married | G12: 105900 | H12: 21 | I12: 38567 | J12: Online Banking | K12: 2 | L12: 8804.34 | M12: 0 | N12: 59 | O12: 87.83 | P12: 5 | Q12: 15000 | R12: 6697.75 | S12: 0 | T12: 0 | U12: 703 | V12: 0
A13: CL00012 | B13: 45 | C13: F | D13: Piemonte | E13: Employee | F13: Married | G13: 49600 | H13: 15 | I13: 40620 | J13: App | K13: 4 | M13: 0 | N13: 30 | O13: 69.35 | P13: 1 | Q13: 5000 | R13: 1097.89 | S13: 0 | T13: 0 | U13: 679 | V13: 0
A14: CL00013 | C14: M | D14: Lombardia | E14: Employee | F14: Married | G14: 38900 | H14: 20 | I14: 38827 | J14: Phone | K14: 2 | L14: 15176.28 | M14: 80694.88 | N14: 13 | O14: 56.28 | P14: 3 | Q14: 8500 | R14: 899.82 | S14: 0 | T14: 0 | U14: 613 | V14: 0
A15: CL00014 | C15: F | D15: Veneto | E15: Teacher | F15: Divorced | G15: 59700 | H15: 10 | I15: 42311 | J15: Online Banking | K15: 1 | L15: 12795 | M15: 36893.27 | N15: 48 | O15: 68.66 | P15: 7 | Q15: 0 | R15: 0 | S15: 0 | T15: 0 | U15: 593 | V15: 0
A16: CL00015 | B16: 42 | C16: M | D16: Sicilia | E16: Self-employed | F16: Single | G16: 52200 | H16: 16 | I16: 40327 | J16: Branch | K16: 4 | L16: 3728.87 | M16: 0 | N16: 33 | O16: 89.35 | P16: 5 | Q16: 7000 | R16: 949.31 | U16: 615 | V16: 0
A17: CL00016 | B17: 31 | C17: M | D17: Sicilia | E17: Self-employed | F17: Married | H17: 0 | I17: 46160 | J17: Branch | K17: 2 | L17: 5266.87 | M17: 0 | N17: 31 | O17: 89.7 | P17: 3 | Q17: 9000 | R17: 1322.05 | S17: 253000 | T17: 1628 | U17: 588 | V17: 0
A18: CL00017 | B18: 43 | C18: M | D18: Campania | E18: Employee | F18: Married | G18: 40700 | H18: 9 | I18: 42938 | J18: App | K18: 3 | L18: 1646.05 | M18: 0 | N18: 35 | O18: 105.7 | P18: 2 | Q18: 6500 | R18: 1763.53 | S18: 184000 | T18: 1282 | U18: 571 | V18: 0
A19: CL00018 | B19: 53 | C19: F | D19: Lazio | E19: Employee | F19: Divorced | G19: 27800 | H19: 19 | I19: 39246 | J19: App | K19: 2 | L19: 5894.62 | M19: 57173.93 | N19: 34 | O19: 50.09 | P19: NA | Q19: 0 | R19: 0 | U19: 643
A20: CL00019 | B20: 20 | C20: M | D20: Sicilia | E20: Employee | F20: Single | G20: 34200 | H20: 1 | I20: 45754 | J20: App | K20: 3 | L20: 1656.94 | M20: 7347.5 | N20: 23 | O20: 60.38 | P20: 0 | Q20: 6500 | R20: 2565.57 | S20: 0 | T20: 0 | U20: 643 | V20: 0
A21: CL00020 | B21: 30 | C21: Unknown | D21: Veneto | E21: Manual worker | F21: Divorced | G21: 14100 | J21: Online Banking | K21: 5 | L21: 672.51 | M21: 3621.8 | N21: 19 | O21: 39.07 | P21: 3 | Q21: 1500 | R21: 593.08 | S21: 0 | T21: 0 | U21: 653
A22: CL00021 | B22: 52 | C22: M | D22: Lombardia | E22: Manual worker | F22: Married | G22: 22400 | H22: 10 | I22: 42446 | J22: Branch | K22: 3 | L22: 2244.58 | M22: 13467.23 | N22: 19 | O22: 28.21 | P22: 1 | S22: 0 | T22: 0 | U22: 623 | V22: 0
A23: CL00022 | B23: 41 | C23: F | D23: Marche | E23: Employee | F23: - | G23: 34800 | H23: 2 | I23: 45375 | J23: App | K23: 2 | L23: 4224.83 | M23: 0 | N23: 30 | O23: 48.02 | P23: 2 | S23: 169000 | U23: 569 | V23: 1
A24: CL00023 | B24: 45 | C24: F | D24: Lazio | E24: Shopkeeper | F24: Married | G24: 28600 | H24: 6 | I24: 44032 | J24: Branch | K24: 2 | L24: 6510.71 | M24: 18628.5 | N24: 23 | O24: 48.33 | P24: 3 | S24: 0 | T24: 0 | U24: 573 | V24: 0
A25: CL00024 | B25: 37 | C25: F | D25: Trentino-Alto Adige | E25: Employee | F25: Married | G25: 24300 | H25: 18 | I25: 39685 | J25: Online Banking | K25: 2 | L25: 6958.53 | M25: 30755.83 | N25: 33 | O25: 38.48 | P25: 1 | Q25: 4000 | R25: 1294.17 | S25: 109000 | T25: 693 | U25: 632 | V25: 0
A26: CL00025 | B26: 51 | C26: M | D26: Piemonte | E26: Employee | F26: Single | G26: 30000 | H26: 10 | I26: 42387 | J26: Branch | K26: 2 | L26: 3700.02 | M26: 10653.7 | N26: 17 | O26: 35.47 | P26: 4 | Q26: 5500 | R26: 209.96 | S26: 82000 | T26: 410 | U26: 661 | V26: 0
A27: CL00026 | B27: 26 | C27: M | D27: Umbria | E27: Employee | F27: Married | G27: 17100 | H27: 5 | I27: 44314 | J27: App | K27: 1 | L27: 1758.1 | M27: 7178.85 | N27: 25 | O27: 58.79 | P27: 1 | S27: 0 | T27: 0 | U27: 641 | V27: 0
A28: CL00027 | B28: 47 | C28: F | D28: Lombardia | E28: Teacher | F28: Married | G28: 35900 | H28: 0 | I28: 46253 | J28: Branch | K28: 3 | L28: 1203.46 | M28: 5520.98 | N28: 21 | O28: 44.29 | P28: 4 | Q28: 0 | R28: 0 | S28: 157000 | T28: 895 | U28: 620
A29: CL00028 | B29: 52 | C29: F | D29: Trentino-Alto Adige | E29: Employee | F29: Married | G29: 25600 | H29: 15 | I29: 40784 | J29: Online Banking | K29: 5 | L29: -307.03 | M29: 0 | N29: 38 | O29: 74.03 | P29: 1 | Q29: 6500 | R29: 3641.59 | S29: 116000 | U29: 613 | V29: 0
A30: CL00029 | B30: 41 | C30: F | D30: Abruzzo | E30: Employee | F30: Single | G30: 23700 | H30: 19 | I30: 39287 | J30: App | K30: 3 | L30: 674.12 | M30: 16518.46 | N30: 27 | O30: 25.96 | P30: 0 | Q30: 3500 | R30: 688.38 | S30: 96000 | T30: 525 | U30: 713 | V30: 0
A31: CL00030 | B31: 38 | C31: F | D31: Campania | E31: Manual worker | F31: Married | G31: 16700 | H31: 8 | I31: 43210 | J31: App | K31: 2 | L31: 531.48 | M31: 0 | N31: 30 | O31: 17.93 | P31: 0 | Q31: 2000 | R31: 546.28 | S31: 0 | T31: 0 | U31: 552 | V31: 1
A32: CL00031 | B32: 44 | C32: M | D32: Abruzzo | E32: Manual worker | F32: Married | G32: 25300 | H32: 13 | I32: 41193 | J32: App | K32: 2 | L32: 2536.09 | M32: 0 | N32: 24 | O32: 56.79 | P32: 1 | Q32: 3500 | R32: 1580.53 | U32: 607 | V32: 0
A33: CL00032 | B33: 66 | C33: M | D33: Veneto | E33: Retired | F33: Divorced | G33: 13100 | H33: 15 | I33: 40635 | J33: Online Banking | K33: 4 | L33: 1386.33 | M33: 17215.76 | N33: 30 | O33: 50.2 | P33: 3 | Q33: 0 | R33: 0 | U33: 624 | V33: 0
A34: CL00033 | B34: 36 | C34: F | D34: Veneto | E34: Employee | F34: Married | G34: 18700 | H34: 12 | I34: 41756 | J34: Branch | K34: 1 | L34: 1371.55 | M34: 16459.23 | N34: 11 | O34: 41.56 | P34: 4 | Q34: 4000 | R34: 1155.74 | S34: 86000 | T34: 617 | U34: 607 | V34: 0
A35: CL00034 | B35: 45 | C35: F | D35: Lazio | E35: Shopkeeper | F35: Single | G35: 23300 | H35: 2 | I35: 25569 | J35: Branch | K35: 1 | L35: 1259.53 | M35: 14213 | N35: 12 | O35: 34.95 | P35: 3 | Q35: 3500 | R35: 1356.12 | S35: 100000 | T35: 643 | U35: 568 | V35: 0
A36: CL00035 | B36: 36 | C36: M | D36: Campania | E36: Self-employed | F36: Married | G36: 51000 | H36: 6 | I36: 43790 | J36: App | K36: 1 | L36: 6099.38 | M36: 22383.75 | N36: 38 | O36: 101.68 | P36: 0 | Q36: 12500 | S36: 0 | T36: 0 | U36: 602
A37: CL00036 | B37: 39 | C37: M | D37: Piemonte | E37: Employee | F37: Married | G37: 22400 | H37: 8 | I37: 43227 | J37: App | K37: 2 | L37: 1467.27 | M37: 9674.73 | N37: 23 | O37: 78.83 | P37: 3 | Q37: 3000 | R37: 1153.09 | S37: 83000 | T37: 445 | U37: 589 | V37: 0
A38: CL00037 | B38: 51 | C38: M | D38: Lombardia | E38: Employee | F38: Married | G38: 21500 | H38: 2 | I38: 45264 | J38: App | K38: 2 | L38: 2144.1 | M38: 6464.68 | N38: 27 | O38: 21.36 | P38: 1 | Q38: 3500 | R38: 1723.34 | S38: 34000 | T38: 163 | U38: 554 | V38: 0
A39: CL00038 | B39: 43 | C39: F | D39: Sardegna | E39: Self-employed | F39: Single | G39: 62500 | H39: 1 | I39: 45797 | J39: Online Banking | K39: 2 | L39: 1634.33 | M39: 9260.84 | N39: 50 | O39: 52.49 | P39: 1 | Q39: 9000 | R39: 770.96 | S39: 0 | T39: 0 | U39: 700
A40: CL00039 | B40: 52 | C40: M | D40: Piemonte | E40: Unemployed | F40: Married | G40: 5300 | H40: 15 | I40: 40470 | J40: App | K40: 3 | L40: 1378.01 | N40: 25 | O40: 51.26 | P40: 2 | Q40: 1000 | R40: 45.67 | U40: 563 | V40: 0
...

Sheet Data_Dictionary
A1: Data dictionary — Customers sheet
A2: Demographic and behavioural extract as of 2026-09-13 for 1,000 retail customers (synthetic data), assembled from three source systems (master data, accounts, cards & loans). 'Expected values' is the plausible range according to the business rules. The second table lists the only missing-value conventions the source systems document: anything else that looks like a placeholder is undocumented and has to be investigated.
A4: Column | B4: Type | C4: Description | D4: Expected values | E4: Excel column
A5: Customer_ID | B5: Text (key) | C5: Unique customer identifier. | D5: Unique; format CL00001 | E5: A
A6: Age | B6: Integer | C6: Customer age in completed years. | D6: 18 – 100 | E6: B
A7: Gender | B7: Categorical | C7: Gender as recorded in the master data. | D7: M, F | E7: C
A8: Region | B8: Categorical | C8: Region of residence (Italy). | D8: One of the 20 Italian regions, standard spelling | E8: D
A9: Occupation | B9: Categorical | C9: Declared occupation. | D9: Employee, Manual worker, Self-employed, Executive, Business owner, Shopkeeper, Teacher, Student, Retired, Unemployed | E9: E
A10: Marital_Status | B10: Categorical | C10: Marital status. | D10: Single, Married, Divorced, Widowed | E10: F
A11: Annual_Income_EUR | B11: Numeric | C11: Declared gross annual income, in euros. | D11: > 0; typically 4,000 – 200,000 | E11: G
A12: Tenure_Years | B12: Integer | C12: Years of relationship with the bank. | D12: 0 – 40 and ≤ Age − 18 | E12: H
A13: Account_Open_Date | B13: Date | C13: Opening date of the first account. | D13: Between 1980 and the extraction date (2026-09-13); consistent with Tenure_Years | E13: I
A14: Preferred_Channel | B14: Categorical | C14: Main contact channel. | D14: Branch, App, Online Banking, Phone | E14: J
A15: Num_Products | B15: Integer | C15: Number of active products (account, cards, mortgage, investments…). | D15: 1 – 6 | E15: K
... A26: Complaints_12M | B26: Integer | C26: Complaints filed in the last 12 months. | D26: 0 – 5 | E26: V
A29: Missing-value conventions documented by the source systems
A30: Column | B30: Code | C30: Meaning
A31: Card_Limit_EUR | B31: 0 | C31: No credit card. A blank is NOT documented.
A32: Monthly_Card_Spend_EUR | B32: 0 | C32: No credit card (always 0 when Card_Limit_EUR is 0).
A33: Mortgage_Balance_EUR | B33: 0 | C33: No mortgage. A blank is NOT documented.
A34: Monthly_Mortgage_Payment_EUR | B34: 0 | C34: No mortgage (always 0 when Mortgage_Balance_EUR is 0).
A35: Avg_Transaction_EUR | B35: (blank) | C35: Undefined when Monthly_Transactions is 0 (dormant account).
A36: Any other column | B36: — | C36: No missing-value code is documented by the source systems.

Sheet Codes
A1: Codes we treat as missing
A2: One list, referenced by every formula in Clean and Missing_Profile: when a new placeholder shows up in a feed we add it here and the whole workbook follows. Case-insensitive; leading/trailing spaces are removed with TRIM before the comparison.
A4: Text placeholder | B4: Where it typically comes from
A5: N/A | B5: Manual data entry, CSV exports
A6: NA | B6: R / statistical exports
A7: n.a. | B7: Manual data entry
A8: n.d. | B8: Italian back-office ('non disponibile')
A9: ? | B9: Legacy data-entry masks
A10: - | B10: Reports where blank cells are rendered as a dash
A11: -- | B11: Same as '-'
A12: Unknown | B12: CRM default category
A13: NULL | B13: Database exports that print NULL literally
A14: None | B14: Python / pandas exports
A17: Numeric sentinels — column-specific, therefore written in the formula of that column
A18: Column | B18: Value | C18: Why we treat it as missing
A19: Age | B19: 0 | C19: An age of 0 is impossible for a bank customer: a default value written by the loader.
A20: Annual_Income_EUR | B20: -999 | C20: Negative income, always the same figure: the classic legacy 'not available' code.
A21: Monthly_Transactions | B21: 9999 | C21: Out of scale and repeated identically; a placeholder, not a heavy user.
A22: Credit_Score | B22: 0 | C22: The score ranges 300 – 850; 0 means 'not computed'.
A23: Account_Open_Date | B23: 1970-01-01 | C23: Unix epoch: what a system writes when the date field was empty at load time.
A26: Values that are NOT missing (recoverable or structural)
A27: Numbers stored as text | B27: e.g. '35000' with the green triangle: AVERAGE, SUM and COUNT skip them silently. Clean converts them with VALUE().
A28: Structural blanks | B28: No card, no mortgage, dormant account, no complaints: the value does not exist. We replace them with the documented constant (0), never with a mean.
A29: Whitespace-only cells | B29: Look empty, but COUNTBLANK does not count them and a filter shows them as a separate item. Clean maps them to a true blank.
A30: 'Unknown' in a categorical column | B30: We normalise it to blank in Clean and then decide, per column, whether to keep an explicit 'Unknown' category (usually yes) or impute the mode.

Sheet Missing_Profile
A1: Missing-value profile — one row per column, all live formulas on the Customers sheet
A2: Step 1: how much is missing, where, and in which disguise. Blank cells are only part of the story: whitespace-only cells, text placeholders (list in Codes) and numeric sentinels (column I, editable) are missing values too; numbers stored as text are not missing but are ignored by every statistical function. The summary on top uses the row-level view of Missing_Matrix.
A4: Cells in the Customers table | B4: =ROWS(Customers!$A$2:$A$1001)*COLUMNS(Customers!$A$1:$V$1) -> 22000
A5: Effective missing cells (blank + whitespace + placeholders + sentinels) | B5: =SUM(K13:K34) -> 1598
A6: % of cells missing | B6: =B5/B4 -> 0.072636364
A7: Rows with at least one missing value | B7: =COUNTIF(Missing_Matrix!$W$2:$W$1001,">0") -> 705
A8: Complete rows (what listwise deletion would keep) | B8: =COUNTIF(Missing_Matrix!$W$2:$W$1001,0) -> 295
A9: Ghost records (only the ID is populated) | B9: =COUNTIF(Missing_Matrix!$Z$2:$Z$1001,"Ghost record") -> 4
A10: Mostly-empty records (more than half of the columns missing) | B10: =COUNTIF(Missing_Matrix!$Z$2:$Z$1001,"Mostly empty") -> 6
A12: # | B12: Column | C12: Col | D12: Type | E12: Rows | F12: Blank cells COUNTBLANK | G12: Whitespace-only LEN(TRIM())=0 | H12: Text placeholders (list in Codes) | I12: Numeric sentinel (edit here) | J12: Sentinel cells COUNTIF | K12: Effective missing | L12: % missing | M12: Numbers stored as text (recoverable) | N12: Of which structural (not applicable) | O12: What we do
A13: 1 | B13: Customer_ID | C13: A | D13: Text (key) | E13: =ROWS(Customers!A$2:A$1001) -> 1000 | F13: =COUNTBLANK(Customers!A$2:A$1001) -> 0 | G13: =SUMPRODUCT((LEN(Customers!A$2:A$1001)>0)*(LEN(TRIM(Customers!A$2:A$1001))=0)) -> 0 | H13: =SUMPRODUCT(--ISNUMBER(MATCH(TRIM(Customers!A$2:A$1001&""),Codes!$A$5:$A$14,0))) -> 0 | J13: =IF(I13="",0,COUNTIF(Customers!A$2:A$1001,I13)) -> 0 | K13: =F13+G13+H13+J13 -> 0 | L13: =K13/E13 -> 0 | M13: =SUMPRODUCT(ISTEXT(Customers!A$2:A$1001)*ISNUMBER(VALUE(Customers!A$2:A$1001))) -> 0 | O13: Key: must never be missing. Ghost records are found through the other columns.
A14: 2 | B14: Age | C14: B | D14: Integer | E14: =ROWS(Customers!B$2:B$1001) -> 1000 | F14: =COUNTBLANK(Customers!B$2:B$1001) -> 24 | G14: =SUMPRODUCT((LEN(Customers!B$2:B$1001)>0)*(LEN(TRIM(Customers!B$2:B$1001))=0)) -> 0 | H14: =SUMPRODUCT(--ISNUMBER(MATCH(TRIM(Customers!B$2:B$1001&""),Codes!$A$5:$A$14,0))) -> 0 | I14: 0 | J14: =IF(I14="",0,COUNTIF(Customers!B$2:B$1001,I14)) -> 10 | K14: =F14+G14+H14+J14 -> 34 | L14: =K14/E14 -> 0.034 | M14: =SUMPRODUCT(ISTEXT(Customers!B$2:B$1001)*ISNUMBER(VALUE(Customers!B$2:B$1001))) -> 0 | O14: Median imputation + missing flag; 0 is treated as missing first.
A15: 3 | B15: Gender | C15: C | D15: Categorical | E15: =ROWS(Customers!C$2:C$1001) -> 1000 | F15: =COUNTBLANK(Customers!C$2:C$1001) -> 14 | G15: =SUMPRODUCT((LEN(Customers!C$2:C$1001)>0)*(LEN(TRIM(Customers!C$2:C$1001))=0)) -> 0 | H15: =SUMPRODUCT(--ISNUMBER(MATCH(TRIM(Customers!C$2:C$1001&""),Codes!$A$5:$A$14,0))) -> 10 | J15: =IF(I15="",0,COUNTIF(Customers!C$2:C$1001,I15)) -> 0 | K15: =F15+G15+H15+J15 -> 24 | L15: =K15/E15 -> 0.024 | M15: =SUMPRODUCT(ISTEXT(Customers!C$2:C$1001)*ISNUMBER(VALUE(Customers!C$2:C$1001))) -> 0 | O15: Keep an explicit 'Unknown' category (mode imputation would hide the information).
A16: 4 | B16: Region | C16: D | D16: Categorical | E16: =ROWS(Customers!D$2:D$1001) -> 1000 | F16: =COUNTBLANK(Customers!D$2:D$1001) -> 14 | G16: =SUMPRODUCT((LEN(Customers!D$2:D$1001)>0)*(LEN(TRIM(Customers!D$2:D$1001))=0)) -> 5 | H16: =SUMPRODUCT(--ISNUMBER(MATCH(TRIM(Customers!D$2:D$1001&""),Codes!$A$5:$A$14,0))) -> 5 | J16: =IF(I16="",0,COUNTIF(Customers!D$2:D$1001,I16)) -> 0 | K16: =F16+G16+H16+J16 -> 24 | L16: =K16/E16 -> 0.024 | M16: =SUMPRODUCT(ISTEXT(Customers!D$2:D$1001)*ISNUMBER(VALUE(Customers!D$2:D$1001))) -> 0 | O16: TRIM, then explicit 'Unknown' category.
A17: 5 | B17: Occupation | C17: E | D17: Categorical | E17: =ROWS(Customers!E$2:E$1001) -> 1000 | F17: =COUNTBLANK(Customers!E$2:E$1001) -> 19 | G17: =SUMPRODUCT((LEN(Customers!E$2:E$1001)>0)*(LEN(TRIM(Customers!E$2:E$1001))=0)) -> 0 | H17: =SUMPRODUCT(--ISNUMBER(MATCH(TRIM(Customers!E$2:E$1001&""),Codes!$A$5:$A$14,0))) -> 5 | J17: =IF(I17="",0,COUNTIF(Customers!E$2:E$1001,I17)) -> 0 | K17: =F17+G17+H17+J17 -> 24 | L17: =K17/E17 -> 0.024 | M17: =SUMPRODUCT(ISTEXT(Customers!E$2:E$1001)*ISNUMBER(VALUE(Customers!E$2:E$1001))) -> 0 | O17: Explicit 'Unknown' category; note that the group-based imputation of Income then needs a fallback.
A18: 6 | B18: Marital_Status | C18: F | D18: Categorical | E18: =ROWS(Customers!F$2:F$1001) -> 1000 | F18: =COUNTBLANK(Customers!F$2:F$1001) -> 14 | G18: =SUMPRODUCT((LEN(Customers!F$2:F$1001)>0)*(LEN(TRIM(Customers!F$2:F$1001))=0)) -> 0 | H18: =SUMPRODUCT(--ISNUMBER(MATCH(TRIM(Customers!F$2:F$1001&""),Codes!$A$5:$A$14,0))) -> 10 | J18: =IF(I18="",0,COUNTIF(Customers!F$2:F$1001,I18)) -> 0 | K18: =F18+G18+H18+J18 -> 24 | L18: =K18/E18 -> 0.024 | M18: =SUMPRODUCT(ISTEXT(Customers!F$2:F$1001)*ISNUMBER(VALUE(Customers!F$2:F$1001))) -> 0 | O18: Explicit 'Unknown' category.
A19: 7 | B19: Annual_Income_EUR | C19: G | D19: Numeric | E19: =ROWS(Customers!G$2:G$1001) -> 1000 | F19: =COUNTBLANK(Customers!G$2:G$1001) -> 52 | G19: =SUMPRODUCT((LEN(Customers!G$2:G$1001)>0)*(LEN(TRIM(Customers!G$2:G$1001))=0)) -> 0 | H19: =SUMPRODUCT(--ISNUMBER(MATCH(TRIM(Customers!G$2:G$1001&""),Codes!$A$5:$A$14,0))) -> 21 | I19: -999 | J19: =IF(I19="",0,COUNTIF(Customers!G$2:G$1001,I19)) -> 10 | K19: =F19+G19+H19+J19 -> 83 | L19: =K19/E19 -> 0.083 | M19: =SUMPRODUCT(ISTEXT(Customers!G$2:G$1001)*ISNUMBER(VALUE(Customers!G$2:G$1001))) -> 6 | O19: Group median by Occupation + missing flag (MAR). Convert the text numbers with VALUE first.
A20: 8 | B20: Tenure_Years | C20: H | D20: Integer | E20: =ROWS(Customers!H$2:H$1001) -> 1000 | F20: =COUNTBLANK(Customers!H$2:H$1001) -> 34 | G20: =SUMPRODUCT((LEN(Customers!H$2:H$1001)>0)*(LEN(TRIM(Customers!H$2:H$1001))=0)) -> 0 | H20: =SUMPRODUCT(--ISNUMBER(MATCH(TRIM(Customers!H$2:H$1001&""),Codes!$A$5:$A$14,0))) -> 0 | J20: =IF(I20="",0,COUNTIF(Customers!H$2:H$1001,I20)) -> 0 | K20: =F20+G20+H20+J20 -> 34 | L20: =K20/E20 -> 0.034 | M20: =SUMPRODUCT(ISTEXT(Customers!H$2:H$1001)*ISNUMBER(VALUE(Customers!H$2:H$1001))) -> 0 | O20: Derive from Account_Open_Date with DATEDIF; median only as a fallback.
A21: 9 | B21: Account_Open_Date | C21: I | D21: Date | E21: =ROWS(Customers!I$2:I$1001) -> 1000 | F21: =COUNTBLANK(Customers!I$2:I$1001) -> 24 | G21: =SUMPRODUCT((LEN(Customers!I$2:I$1001)>0)*(LEN(TRIM(Customers!I$2:I$1001))=0)) -> 0 | H21: =SUMPRODUCT(--ISNUMBER(MATCH(TRIM(Customers!I$2:I$1001&""),Codes!$A$5:$A$14,0))) -> 0 | I21: 25569 | J21: =IF(I21="",0,COUNTIF(Customers!I$2:I$1001,I21)) -> 8 | K21: =F21+G21+H21+J21 -> 32 | L21: =K21/E21 -> 0.032 | M21: =SUMPRODUCT(ISTEXT(Customers!I$2:I$1001)*ISNUMBER(VALUE(Customers!I$2:I$1001))) -> 0 | O21: Derive from Tenure_Years (approximate) or leave blank; never impute a mean date.
A22: 10 | B22: Preferred_Channel | C22: J | D22: Categorical | E22: =ROWS(Customers!J$2:J$1001) -> 1000 | F22: =COUNTBLANK(Customers!J$2:J$1001) -> 20 | G22: =SUMPRODUCT((LEN(Customers!J$2:J$1001)>0)*(LEN(TRIM(Customers!J$2:J$1001))=0)) -> 0 | H22: =SUMPRODUCT(--ISNUMBER(MATCH(TRIM(Customers!J$2:J$1001&""),Codes!$A$5:$A$14,0))) -> 15 | J22: =IF(I22="",0,COUNTIF(Customers!J$2:J$1001,I22)) -> 0 | K22: =F22+G22+H22+J22 -> 35 | L22: =K22/E22 -> 0.035 | M22: =SUMPRODUCT(ISTEXT(Customers!J$2:J$1001)*ISNUMBER(VALUE(Customers!J$2:J$1001))) -> 0 | O22: Explicit 'Unknown' category — compare with the mode in Strategies.
A23: 11 | B23: Num_Products | C23: K | D23: Integer | E23: =ROWS(Customers!K$2:K$1001) -> 1000 | F23: =COUNTBLANK(Customers!K$2:K$1001) -> 20 | G23: =SUMPRODUCT((LEN(Customers!K$2:K$1001)>0)*(LEN(TRIM(Customers!K$2:K$1001))=0)) -> 0 | H23: =SUMPRODUCT(--ISNUMBER(MATCH(TRIM(Customers!K$2:K$1001&""),Codes!$A$5:$A$14,0))) -> 15 | J23: =IF(I23="",0,COUNTIF(Customers!K$2:K$1001,I23)) -> 0 | K23: =F23+G23+H23+J23 -> 35 | L23: =K23/E23 -> 0.035 | M23: =SUMPRODUCT(ISTEXT(Customers!K$2:K$1001)*ISNUMBER(VALUE(Customers!K$2:K$1001))) -> 0 | O23: Median (integer) imputation.
A24: 12 | B24: Checking_Balance_EUR | C24: L | D24: Numeric | E24: =ROWS(Customers!L$2:L$1001) -> 1000 | F24: =COUNTBLANK(Customers!L$2:L$1001) -> 30 | G24: =SUMPRODUCT((LEN(Customers!L$2:L$1001)>0)*(LEN(TRIM(Customers!L$2:L$1001))=0)) -> 0 | H24: =SUMPRODUCT(--ISNUMBER(MATCH(TRIM(Customers!L$2:L$1001&""),Codes!$A$5:$A$14,0))) -> 0 | J24: =IF(I24="",0,COUNTIF(Customers!L$2:L$1001,I24)) -> 0 | K24: =F24+G24+H24+J24 -> 30 | L24: =K24/E24 -> 0.03 | M24: =SUMPRODUCT(ISTEXT(Customers!L$2:L$1001)*ISNUMBER(VALUE(Customers!L$2:L$1001))) -> 0 | O24: Median imputation.
A25: 13 | B25: Savings_Balance_EUR | C25: M | D25: Numeric | E25: =ROWS(Customers!M$2:M$1001) -> 1000 | F25: =COUNTBLANK(Customers!M$2:M$1001) -> 84 | G25: =SUMPRODUCT((LEN(Customers!M$2:M$1001)>0)*(LEN(TRIM(Customers!M$2:M$1001))=0)) -> 0 | H25: =SUMPRODUCT(--ISNUMBER(MATCH(TRIM(Customers!M$2:M$1001&""),Codes!$A$5:$A$14,0))) -> 0 | J25: =IF(I25="",0,COUNTIF(Customers!M$2:M$1001,I25)) -> 0 | K25: =F25+G25+H25+J25 -> 84 | L25: =K25/E25 -> 0.084 | M25: =SUMPRODUCT(ISTEXT(Customers!M$2:M$1001)*ISNUMBER(VALUE(Customers!M$2:M$1001))) -> 0 | O25: Missing rate grows with wealth (MNAR): no single value is unbiased. Median + flag, and ask the data owner.
A26: 14 | B26: Monthly_Transactions | C26: N | D26: Integer | E26: =ROWS(Customers!N$2:N$1001) -> 1000 | F26: =COUNTBLANK(Customers!N$2:N$1001) -> 20 | G26: =SUMPRODUCT((LEN(Customers!N$2:N$1001)>0)*(LEN(TRIM(Customers!N$2:N$1001))=0)) -> 0 | H26: =SUMPRODUCT(--ISNUMBER(MATCH(TRIM(Customers!N$2:N$1001&""),Codes!$A$5:$A$14,0))) -> 0 | I26: 9999 | J26: =IF(I26="",0,COUNTIF(Customers!N$2:N$1001,I26)) -> 10 | K26: =F26+G26+H26+J26 -> 30 | L26: =K26/E26 -> 0.03 | M26: =SUMPRODUCT(ISTEXT(Customers!N$2:N$1001)*ISNUMBER(VALUE(Customers!N$2:N$1001))) -> 0 | O26: 9999 is a sentinel; the 0s are real (dormant accounts). Median for the true blanks.
A27: 15 | B27: Avg_Transaction_EUR | C27: O | D27: Numeric | E27: =ROWS(Customers!O$2:O$1001) -> 1000 | F27: =COUNTBLANK(Customers!O$2:O$1001) -> 45 | G27: =SUMPRODUCT((LEN(Customers!O$2:O$1001)>0)*(LEN(TRIM(Customers!O$2:O$1001))=0)) -> 0 | H27: =SUMPRODUCT(--ISNUMBER(MATCH(TRIM(Customers!O$2:O$1001&""),Codes!$A$5:$A$14,0))) -> 0 | J27: =IF(I27="",0,COUNTIF(Customers!O$2:O$1001,I27)) -> 0 | K27: =F27+G27+H27+J27 -> 45 | L27: =K27/E27 -> 0.045 | M27: =SUMPRODUCT(ISTEXT(Customers!O$2:O$1001)*ISNUMBER(VALUE(Customers!O$2:O$1001))) -> 0 | N27: =COUNTIFS(Customers!O$2:O$1001,"",Customers!N$2:N$1001,0) -> 20 | O27: Structural when Monthly_Transactions = 0 (leave blank or 0); median for the other blanks.
A28: 16 | B28: Monthly_ATM_Withdrawals | C28: P | D28: Integer | E28: =ROWS(Customers!P$2:P$1001) -> 1000 | F28: =COUNTBLANK(Customers!P$2:P$1001) -> 20 | G28: =SUMPRODUCT((LEN(Customers!P$2:P$1001)>0)*(LEN(TRIM(Customers!P$2:P$1001))=0)) -> 0 | H28: =SUMPRODUCT(--ISNUMBER(MATCH(TRIM(Customers!P$2:P$1001&""),Codes!$A$5:$A$14,0))) -> 5 | J28: =IF(I28="",0,COUNTIF(Customers!P$2:P$1001,I28)) -> 0 | K28: =F28+G28+H28+J28 -> 25 | L28: =K28/E28 -> 0.025 | M28: =SUMPRODUCT(ISTEXT(Customers!P$2:P$1001)*ISNUMBER(VALUE(Customers!P$2:P$1001))) -> 0 | O28: Median imputation; 'NA' is a text placeholder.
A29: 17 | B29: Card_Limit_EUR | C29: Q | D29: Numeric | E29: =ROWS(Customers!Q$2:Q$1001) -> 1000 | F29: =COUNTBLANK(Customers!Q$2:Q$1001) -> 127 | G29: =SUMPRODUCT((LEN(Customers!Q$2:Q$1001)>0)*(LEN(TRIM(Customers!Q$2:Q$1001))=0)) -> 0 | H29: =SUMPRODUCT(--ISNUMBER(MATCH(TRIM(Customers!Q$2:Q$1001&""),Codes!$A$5:$A$14,0))) -> 0 | J29: =IF(I29="",0,COUNTIF(Customers!Q$2:Q$1001,I29)) -> 0 | K29: =F29+G29+H29+J29 -> 127 | L29: =K29/E29 -> 0.127 | M29: =SUMPRODUCT(ISTEXT(Customers!Q$2:Q$1001)*ISNUMBER(VALUE(Customers!Q$2:Q$1001))) -> 0 | N29: =COUNTIFS(Customers!Q$2:Q$1001,"",Customers!R$2:R$1001,"") -> 119 | O29: Blank + blank spend = no card → 0. Blank with a spend present = genuinely missing → verify.
A30: 18 | B30: Monthly_Card_Spend_EUR | C30: R | D30: Numeric | E30: =ROWS(Customers!R$2:R$1001) -> 1000 | F30: =COUNTBLANK(Customers!R$2:R$1001) -> 134 | G30: =SUMPRODUCT((LEN(Customers!R$2:R$1001)>0)*(LEN(TRIM(Customers!R$2:R$1001))=0)) -> 0 | H30: =SUMPRODUCT(--ISNUMBER(MATCH(TRIM(Customers!R$2:R$1001&""),Codes!$A$5:$A$14,0))) -> 0 | J30: =IF(I30="",0,COUNTIF(Customers!R$2:R$1001,I30)) -> 0 | K30: =F30+G30+H30+J30 -> 134 | L30: =K30/E30 -> 0.134 | M30: =SUMPRODUCT(ISTEXT(Customers!R$2:R$1001)*ISNUMBER(VALUE(Customers!R$2:R$1001))) -> 0 | N30: =COUNTIFS(Customers!Q$2:Q$1001,"",Customers!R$2:R$1001,"") -> 119 | O30: Blank + blank limit = no card → 0. Blank with a limit present → limit × average spend/limit ratio.
A31: 19 | B31: Mortgage_Balance_EUR | C31: S | D31: Numeric | E31: =ROWS(Customers!S$2:S$1001) -> 1000 | F31: =COUNTBLANK(Customers!S$2:S$1001) -> 256 | G31: =SUMPRODUCT((LEN(Customers!S$2:S$1001)>0)*(LEN(TRIM(Customers!S$2:S$1001))=0)) -> 0 | H31: =SUMPRODUCT(--ISNUMBER(MATCH(TRIM(Customers!S$2:S$1001&""),Codes!$A$5:$A$14,0))) -> 0 | J31: =IF(I31="",0,COUNTIF(Customers!S$2:S$1001,I31)) -> 0 | K31: =F31+G31+H31+J31 -> 256 | L31: =K31/E31 -> 0.256 | M31: =SUMPRODUCT(ISTEXT(Customers!S$2:S$1001)*ISNUMBER(VALUE(Customers!S$2:S$1001))) -> 0 | N31: =COUNTIFS(Customers!S$2:S$1001,"",Customers!T$2:T$1001,"") -> 251 | O31: Blank + blank payment = no mortgage → 0. Blank with a payment present → verify.
A32: 20 | B32: Monthly_Mortgage_Payment_EUR | C32: T | D32: Numeric | E32: =ROWS(Customers!T$2:T$1001) -> 1000 | F32: =COUNTBLANK(Customers!T$2:T$1001) -> 261 | G32: =SUMPRODUCT((LEN(Customers!T$2:T$1001)>0)*(LEN(TRIM(Customers!T$2:T$1001))=0)) -> 0 | H32: =SUMPRODUCT(--ISNUMBER(MATCH(TRIM(Customers!T$2:T$1001&""),Codes!$A$5:$A$14,0))) -> 0 | J32: =IF(I32="",0,COUNTIF(Customers!T$2:T$1001,I32)) -> 0 | K32: =F32+G32+H32+J32 -> 261 | L32: =K32/E32 -> 0.261 | M32: =SUMPRODUCT(ISTEXT(Customers!T$2:T$1001)*ISNUMBER(VALUE(Customers!T$2:T$1001))) -> 0 | N32: =COUNTIFS(Customers!S$2:S$1001,"",Customers!T$2:T$1001,"") -> 251 | O32: Blank + blank balance = no mortgage → 0. Blank with a balance present → balance × average payment/balance ratio.
A33: 21 | B33: Credit_Score | C33: U | D33: Integer | E33: =ROWS(Customers!U$2:U$1001) -> 1000 | F33: =COUNTBLANK(Customers!U$2:U$1001) -> 35 | G33: =SUMPRODUCT((LEN(Customers!U$2:U$1001)>0)*(LEN(TRIM(Customers!U$2:U$1001))=0)) -> 0 | H33: =SUMPRODUCT(--ISNUMBER(MATCH(TRIM(Customers!U$2:U$1001&""),Codes!$A$5:$A$14,0))) -> 0 | I33: 0 | J33: =IF(I33="",0,COUNTIF(Customers!U$2:U$1001,I33)) -> 8 | K33: =F33+G33+H33+J33 -> 43 | L33: =K33/E33 -> 0.043 | M33: =SUMPRODUCT(ISTEXT(Customers!U$2:U$1001)*ISNUMBER(VALUE(Customers!U$2:U$1001))) -> 0 | O33: Mean (symmetric distribution) or median; 0 is a sentinel.
A34: 22 | B34: Complaints_12M | C34: V | D34: Integer | E34: =ROWS(Customers!V$2:V$1001) -> 1000 | F34: =COUNTBLANK(Customers!V$2:V$1001) -> 214 | G34: =SUMPRODUCT((LEN(Customers!V$2:V$1001)>0)*(LEN(TRIM(Customers!V$2:V$1001))=0)) -> 0 | H34: =SUMPRODUCT(--ISNUMBER(MATCH(TRIM(Customers!V$2:V$1001&""),Codes!$A$5:$A$14,0))) -> 0 | J34: =IF(I34="",0,COUNTIF(Customers!V$2:V$1001,I34)) -> 0 | K34: =F34+G34+H34+J34 -> 214 | L34: =K34/E34 -> 0.214 | M34: =SUMPRODUCT(ISTEXT(Customers!V$2:V$1001)*ISNUMBER(VALUE(Customers!V$2:V$1001))) -> 0 | N34: ? — a blank may mean 0, ask the data owner | O34: Blank probably means 0, but not always: constant 0 + missing flag, and ask the data owner.
B35: Total | F35: =SUM(F13:F34) -> 1461 | G35: =SUM(G13:G34) -> 5 | H35: =SUM(H13:H34) -> 86 | J35: =SUM(J13:J34) -> 46 | K35: =SUM(K13:K34) -> 1598 | L35: =K35/B4 -> 0.072636364 | M35: =SUM(M13:M34) -> 6
A37: Reading the table: 'Effective missing' = blank + whitespace + placeholder + sentinel. The Codes sheet holds the placeholder list; the sentinel in column I can be changed and the counts follow. Numbers stored as text are counted separately because they are recoverable with VALUE(), yet AVERAGE/SUM/COUNT ignore them until we convert them.

Sheet Missing_Matrix
A1: Customer_ID | B1: Age | C1: Gender | D1: Region | E1: Occupation | F1: Marital_Status | G1: Annual_Income_EUR | H1: Tenure_Years | I1: Account_Open_Date | J1: Preferred_Channel | K1: Num_Products | L1: Checking_Balance_EUR | M1: Savings_Balance_EUR | N1: Monthly_Transactions | O1: Avg_Transaction_EUR | P1: Monthly_ATM_Withdrawals | Q1: Card_Limit_EUR | R1: Monthly_Card_Spend_EUR | S1: Mortgage_Balance_EUR | T1: Monthly_Mortgage_Payment_EUR | U1: Credit_Score | V1: Complaints_12M | W1: Missing cells in row | X1: Status | Y1: % of columns missing | Z1: Record type
A2: =Clean!A2 -> CL00001 | B2: =IF(Clean!B2="",1,0) -> 0 | C2: =IF(Clean!C2="",1,0) -> 0 | D2: =IF(Clean!D2="",1,0) -> 0 | E2: =IF(Clean!E2="",1,0) -> 0 | F2: =IF(Clean!F2="",1,0) -> 0 | G2: =IF(Clean!G2="",1,0) -> 0 | H2: =IF(Clean!H2="",1,0) -> 0 | I2: =IF(Clean!I2="",1,0) -> 0 | ... V2: =IF(Clean!V2="",1,0) -> 1 | W2: =SUM(B2:V2) -> 3 | X2: =IF(W2=0,"Complete","Incomplete") -> Incomplete | Y2: =W2/21 -> 0.14285714 | Z2: =IF(W2=21,"Ghost record",IF(W2>=11,"Mostly empty",IF(W2=0,"Complete","Partial"))) -> Partial
A3: =Clean!A3 -> CL00002 | B3: =IF(Clean!B3="",1,0) -> 0 | C3: =IF(Clean!C3="",1,0) -> 0 | D3: =IF(Clean!D3="",1,0) -> 0 | E3: =IF(Clean!E3="",1,0) -> 0 | F3: =IF(Clean!F3="",1,0) -> 0 | G3: =IF(Clean!G3="",1,0) -> 0 | H3: =IF(Clean!H3="",1,0) -> 0 | I3: =IF(Clean!I3="",1,0) -> 0 | ... V3: =IF(Clean!V3="",1,0) -> 1 | W3: =SUM(B3:V3) -> 1 | X3: =IF(W3=0,"Complete","Incomplete") -> Incomplete | Y3: =W3/21 -> 0.047619048 | Z3: =IF(W3=21,"Ghost record",IF(W3>=11,"Mostly empty",IF(W3=0,"Complete","Partial"))) -> Partial
A4: =Clean!A4 -> CL00003 | B4: =IF(Clean!B4="",1,0) -> 0 | C4: =IF(Clean!C4="",1,0) -> 0 | D4: =IF(Clean!D4="",1,0) -> 0 | E4: =IF(Clean!E4="",1,0) -> 0 | F4: =IF(Clean!F4="",1,0) -> 0 | G4: =IF(Clean!G4="",1,0) -> 0 | H4: =IF(Clean!H4="",1,0) -> 0 | I4: =IF(Clean!I4="",1,0) -> 0 | ... V4: =IF(Clean!V4="",1,0) -> 1 | W4: =SUM(B4:V4) -> 3 | X4: =IF(W4=0,"Complete","Incomplete") -> Incomplete | Y4: =W4/21 -> 0.14285714 | Z4: =IF(W4=21,"Ghost record",IF(W4>=11,"Mostly empty",IF(W4=0,"Complete","Partial"))) -> Partial
A5: =Clean!A5 -> CL00004 | B5: =IF(Clean!B5="",1,0) -> 0 | C5: =IF(Clean!C5="",1,0) -> 0 | D5: =IF(Clean!D5="",1,0) -> 0 | E5: =IF(Clean!E5="",1,0) -> 0 | F5: =IF(Clean!F5="",1,0) -> 0 | G5: =IF(Clean!G5="",1,0) -> 0 | H5: =IF(Clean!H5="",1,0) -> 0 | I5: =IF(Clean!I5="",1,0) -> 0 | ... V5: =IF(Clean!V5="",1,0) -> 0 | W5: =SUM(B5:V5) -> 0 | X5: =IF(W5=0,"Complete","Incomplete") -> Complete | Y5: =W5/21 -> 0 | Z5: =IF(W5=21,"Ghost record",IF(W5>=11,"Mostly empty",IF(W5=0,"Complete","Partial"))) -> Complete
A6: =Clean!A6 -> CL00005 | B6: =IF(Clean!B6="",1,0) -> 0 | C6: =IF(Clean!C6="",1,0) -> 0 | D6: =IF(Clean!D6="",1,0) -> 0 | E6: =IF(Clean!E6="",1,0) -> 0 | F6: =IF(Clean!F6="",1,0) -> 0 | G6: =IF(Clean!G6="",1,0) -> 0 | H6: =IF(Clean!H6="",1,0) -> 0 | I6: =IF(Clean!I6="",1,0) -> 0 | ... V6: =IF(Clean!V6="",1,0) -> 0 | W6: =SUM(B6:V6) -> 2 | X6: =IF(W6=0,"Complete","Incomplete") -> Incomplete | Y6: =W6/21 -> 0.095238095 | Z6: =IF(W6=21,"Ghost record",IF(W6>=11,"Mostly empty",IF(W6=0,"Complete","Partial"))) -> Partial
A7: =Clean!A7 -> CL00006 | B7: =IF(Clean!B7="",1,0) -> 0 | C7: =IF(Clean!C7="",1,0) -> 0 | D7: =IF(Clean!D7="",1,0) -> 0 | E7: =IF(Clean!E7="",1,0) -> 0 | F7: =IF(Clean!F7="",1,0) -> 0 | G7: =IF(Clean!G7="",1,0) -> 0 | H7: =IF(Clean!H7="",1,0) -> 0 | I7: =IF(Clean!I7="",1,0) -> 0 | ... V7: =IF(Clean!V7="",1,0) -> 0 | W7: =SUM(B7:V7) -> 1 | X7: =IF(W7=0,"Complete","Incomplete") -> Incomplete | Y7: =W7/21 -> 0.047619048 | Z7: =IF(W7=21,"Ghost record",IF(W7>=11,"Mostly empty",IF(W7=0,"Complete","Partial"))) -> Partial
A8: =Clean!A8 -> CL00007 | B8: =IF(Clean!B8="",1,0) -> 0 | C8: =IF(Clean!C8="",1,0) -> 0 | D8: =IF(Clean!D8="",1,0) -> 0 | E8: =IF(Clean!E8="",1,0) -> 0 | F8: =IF(Clean!F8="",1,0) -> 0 | G8: =IF(Clean!G8="",1,0) -> 0 | H8: =IF(Clean!H8="",1,0) -> 0 | I8: =IF(Clean!I8="",1,0) -> 0 | ... V8: =IF(Clean!V8="",1,0) -> 1 | W8: =SUM(B8:V8) -> 3 | X8: =IF(W8=0,"Complete","Incomplete") -> Incomplete | Y8: =W8/21 -> 0.14285714 | Z8: =IF(W8=21,"Ghost record",IF(W8>=11,"Mostly empty",IF(W8=0,"Complete","Partial"))) -> Partial
A9: =Clean!A9 -> CL00008 | B9: =IF(Clean!B9="",1,0) -> 0 | C9: =IF(Clean!C9="",1,0) -> 0 | D9: =IF(Clean!D9="",1,0) -> 0 | E9: =IF(Clean!E9="",1,0) -> 0 | F9: =IF(Clean!F9="",1,0) -> 0 | G9: =IF(Clean!G9="",1,0) -> 0 | H9: =IF(Clean!H9="",1,0) -> 0 | I9: =IF(Clean!I9="",1,0) -> 0 | ... V9: =IF(Clean!V9="",1,0) -> 0 | W9: =SUM(B9:V9) -> 0 | X9: =IF(W9=0,"Complete","Incomplete") -> Complete | Y9: =W9/21 -> 0 | Z9: =IF(W9=21,"Ghost record",IF(W9>=11,"Mostly empty",IF(W9=0,"Complete","Partial"))) -> Complete
A10: =Clean!A10 -> CL00009 | B10: =IF(Clean!B10="",1,0) -> 0 | C10: =IF(Clean!C10="",1,0) -> 0 | D10: =IF(Clean!D10="",1,0) -> 0 | E10: =IF(Clean!E10="",1,0) -> 0 | F10: =IF(Clean!F10="",1,0) -> 1 | G10: =IF(Clean!G10="",1,0) -> 0 | H10: =IF(Clean!H10="",1,0) -> 0 | I10: =IF(Clean!I10="",1,0) -> 0 | ... V10: =IF(Clean!V10="",1,0) -> 0 | W10: =SUM(B10:V10) -> 1 | X10: =IF(W10=0,"Complete","Incomplete") -> Incomplete | Y10: =W10/21 -> 0.047619048 | Z10: =IF(W10=21,"Ghost record",IF(W10>=11,"Mostly empty",IF(W10=0,"Complete","Partial"))) -> Partial
A11: =Clean!A11 -> CL00010 | B11: =IF(Clean!B11="",1,0) -> 0 | C11: =IF(Clean!C11="",1,0) -> 0 | D11: =IF(Clean!D11="",1,0) -> 0 | E11: =IF(Clean!E11="",1,0) -> 0 | F11: =IF(Clean!F11="",1,0) -> 0 | G11: =IF(Clean!G11="",1,0) -> 0 | H11: =IF(Clean!H11="",1,0) -> 0 | I11: =IF(Clean!I11="",1,0) -> 0 | ... V11: =IF(Clean!V11="",1,0) -> 1 | W11: =SUM(B11:V11) -> 1 | X11: =IF(W11=0,"Complete","Incomplete") -> Incomplete | Y11: =W11/21 -> 0.047619048 | Z11: =IF(W11=21,"Ghost record",IF(W11>=11,"Mostly empty",IF(W11=0,"Complete","Partial"))) -> Partial
A12: =Clean!A12 -> CL00011 | B12: =IF(Clean!B12="",1,0) -> 0 | C12: =IF(Clean!C12="",1,0) -> 0 | D12: =IF(Clean!D12="",1,0) -> 0 | E12: =IF(Clean!E12="",1,0) -> 0 | F12: =IF(Clean!F12="",1,0) -> 0 | G12: =IF(Clean!G12="",1,0) -> 0 | H12: =IF(Clean!H12="",1,0) -> 0 | I12: =IF(Clean!I12="",1,0) -> 0 | ... V12: =IF(Clean!V12="",1,0) -> 0 | W12: =SUM(B12:V12) -> 0 | X12: =IF(W12=0,"Complete","Incomplete") -> Complete | Y12: =W12/21 -> 0 | Z12: =IF(W12=21,"Ghost record",IF(W12>=11,"Mostly empty",IF(W12=0,"Complete","Partial"))) -> Complete
A13: =Clean!A13 -> CL00012 | B13: =IF(Clean!B13="",1,0) -> 0 | C13: =IF(Clean!C13="",1,0) -> 0 | D13: =IF(Clean!D13="",1,0) -> 0 | E13: =IF(Clean!E13="",1,0) -> 0 | F13: =IF(Clean!F13="",1,0) -> 0 | G13: =IF(Clean!G13="",1,0) -> 0 | H13: =IF(Clean!H13="",1,0) -> 0 | I13: =IF(Clean!I13="",1,0) -> 0 | ... V13: =IF(Clean!V13="",1,0) -> 0 | W13: =SUM(B13:V13) -> 1 | X13: =IF(W13=0,"Complete","Incomplete") -> Incomplete | Y13: =W13/21 -> 0.047619048 | Z13: =IF(W13=21,"Ghost record",IF(W13>=11,"Mostly empty",IF(W13=0,"Complete","Partial"))) -> Partial
... A1001: =Clean!A1001 -> CL01000 | B1001: =IF(Clean!B1001="",1,0) -> 0 | C1001: =IF(Clean!C1001="",1,0) -> 0 | D1001: =IF(Clean!D1001="",1,0) -> 0 | E1001: =IF(Clean!E1001="",1,0) -> 1 | F1001: =IF(Clean!F1001="",1,0) -> 0 | G1001: =IF(Clean!G1001="",1,0) -> 0 | H1001: =IF(Clean!H1001="",1,0) -> 0 | I1001: =IF(Clean!I1001="",1,0) -> 0 | ... V1001: =IF(Clean!V1001="",1,0) -> 0 | W1001: =SUM(B1001:V1001) -> 1 | X1001: =IF(W1001=0,"Complete","Incomplete") -> Incomplete | Y1001: =W1001/21 -> 0.047619048 | Z1001: =IF(W1001=21,"Ghost record",IF(W1001>=11,"Mostly empty",IF(W1001=0,"Complete","Partial"))) -> Partial
A1003: Missing per column | B1003: =SUM(B2:B1001) -> 34 | C1003: =SUM(C2:C1001) -> 24 | D1003: =SUM(D2:D1001) -> 24 | E1003: =SUM(E2:E1001) -> 24 | F1003: =SUM(F2:F1001) -> 24 | G1003: =SUM(G2:G1001) -> 83 | H1003: =SUM(H2:H1001) -> 34 | I1003: =SUM(I2:I1001) -> 32 | ... V1003: =SUM(V2:V1001) -> 214
A1004: % missing | B1004: =B1003/1000 -> 0.034 | C1004: =C1003/1000 -> 0.024 | D1004: =D1003/1000 -> 0.024 | E1004: =E1003/1000 -> 0.024 | F1004: =F1003/1000 -> 0.024 | G1004: =G1003/1000 -> 0.083 | H1004: =H1003/1000 -> 0.034 | I1004: =I1003/1000 -> 0.032 | ... V1004: =V1003/1000 -> 0.214

Sheet Clean
A1: Customer_ID | B1: Age | C1: Gender | D1: Region | E1: Occupation | F1: Marital_Status | G1: Annual_Income_EUR | H1: Tenure_Years | I1: Account_Open_Date | J1: Preferred_Channel | K1: Num_Products | L1: Checking_Balance_EUR | M1: Savings_Balance_EUR | N1: Monthly_Transactions | O1: Avg_Transaction_EUR | P1: Monthly_ATM_Withdrawals | Q1: Card_Limit_EUR | R1: Monthly_Card_Spend_EUR | S1: Mortgage_Balance_EUR | T1: Monthly_Mortgage_Payment_EUR | U1: Credit_Score | V1: Complaints_12M
A2: =Customers!A2 -> CL00001 | B2: =IF(OR(TRIM(Customers!B2&"")="",ISNUMBER(MATCH(TRIM(Customers!B2&""),Codes!$A$5:$A$14,0)),Customers!B2=0),"",IF(ISNUMBER(Customers!B2),Customers!B2,IFERROR(VALUE(Customers!B2),""))) -> 57 | C2: =IF(OR(TRIM(Customers!C2&"")="",ISNUMBER(MATCH(TRIM(Customers!C2&""),Codes!$A$5:$A$14,0))),"",TRIM(Customers!C2)) -> F | D2: =IF(OR(TRIM(Customers!D2&"")="",ISNUMBER(MATCH(TRIM(Customers!D2&""),Codes!$A$5:$A$14,0))),"",TRIM(Customers!D2)) -> Marche | E2: =IF(OR(TRIM(Customers!E2&"")="",ISNUMBER(MATCH(TRIM(Customers!E2&""),Codes!$A$5:$A$14,0))),"",TRIM(Customers!E2)) -> Shopkeeper | F2: =IF(OR(TRIM(Customers!F2&"")="",ISNUMBER(MATCH(TRIM(Customers!F2&""),Codes!$A$5:$A$14,0))),"",TRIM(Customers!F2)) -> Married | G2: =IF(OR(TRIM(Customers!G2&"")="",ISNUMBER(MATCH(TRIM(Customers!G2&""),Codes!$A$5:$A$14,0)),Customers!G2=-999),"",IF(ISNUMBER(Customers!G2),Customers!G2,IFERROR(VALUE(Customers!G2),""))) -> 30100 | H2: =IF(OR(TRIM(Customers!H2&"")="",ISNUMBER(MATCH(TRIM(Customers!H2&""),Codes!$A$5:$A$14,0))),"",IF(ISNUMBER(Customers!H2),Customers!H2,IFERROR(VALUE(Customers!H2),""))) -> 4 | I2: =IF(OR(TRIM(Customers!I2&"")="",ISNUMBER(MATCH(TRIM(Customers!I2&""),Codes!$A$5:$A$14,0)),Customers!I2=DATE(1970,1,1)),"",IF(ISNUMBER(Customers!I2),Customers!I2,IFERROR(DATEVALUE(Customers!I2),""))) -> 44721 | J2: =IF(OR(TRIM(Customers!J2&"")="",ISNUMBER(MATCH(TRIM(Customers!J2&""),Codes!$A$5:$A$14,0))),"",TRIM(Customers!J2)) -> Branch | K2: =IF(OR(TRIM(Customers!K2&"")="",ISNUMBER(MATCH(TRIM(Customers!K2&""),Codes!$A$5:$A$14,0))),"",IF(ISNUMBER(Customers!K2),Customers!K2,IFERROR(VALUE(Customers!K2),""))) -> 2 | L2: =IF(OR(TRIM(Customers!L2&"")="",ISNUMBER(MATCH(TRIM(Customers!L2&""),Codes!$A$5:$A$14,0))),"",IF(ISNUMBER(Customers!L2),Customers!L2,IFERROR(VALUE(Customers!L2),""))) -> 6763.27 | M2: =IF(OR(TRIM(Customers!M2&"")="",ISNUMBER(MATCH(TRIM(Customers!M2&""),Codes!$A$5:$A$14,0))),"",IF(ISNUMBER(Customers!M2),Customers!M2,IFERROR(VALUE(Customers!M2),""))) -> 12100.75 | N2: =IF(OR(TRIM(Customers!N2&"")="",ISNUMBER(MATCH(TRIM(Customers!N2&""),Codes!$A$5:$A$14,0)),Customers!N2=9999),"",IF(ISNUMBER(Customers!N2),Customers!N2,IFERROR(VALUE(Customers!N2),""))) -> 23 | O2: =IF(OR(TRIM(Customers!O2&"")="",ISNUMBER(MATCH(TRIM(Customers!O2&""),Codes!$A$5:$A$14,0))),"",IF(ISNUMBER(Customers!O2),Customers!O2,IFERROR(VALUE(Customers!O2),""))) -> 36.84 | P2: =IF(OR(TRIM(Customers!P2&"")="",ISNUMBER(MATCH(TRIM(Customers!P2&""),Codes!$A$5:$A$14,0))),"",IF(ISNUMBER(Customers!P2),Customers!P2,IFERROR(VALUE(Customers!P2),""))) -> 1 | Q2: =IF(OR(TRIM(Customers!Q2&"")="",ISNUMBER(MATCH(TRIM(Customers!Q2&""),Codes!$A$5:$A$14,0))),"",IF(ISNUMBER(Customers!Q2),Customers!Q2,IFERROR(VALUE(Customers!Q2),""))) | R2: =IF(OR(TRIM(Customers!R2&"")="",ISNUMBER(MATCH(TRIM(Customers!R2&""),Codes!$A$5:$A$14,0))),"",IF(ISNUMBER(Customers!R2),Customers!R2,IFERROR(VALUE(Customers!R2),""))) | S2: =IF(OR(TRIM(Customers!S2&"")="",ISNUMBER(MATCH(TRIM(Customers!S2&""),Codes!$A$5:$A$14,0))),"",IF(ISNUMBER(Customers!S2),Customers!S2,IFERROR(VALUE(Customers!S2),""))) -> 93000 | T2: =IF(OR(TRIM(Customers!T2&"")="",ISNUMBER(MATCH(TRIM(Customers!T2&""),Codes!$A$5:$A$14,0))),"",IF(ISNUMBER(Customers!T2),Customers!T2,IFERROR(VALUE(Customers!T2),""))) -> 603 | U2: =IF(OR(TRIM(Customers!U2&"")="",ISNUMBER(MATCH(TRIM(Customers!U2&""),Codes!$A$5:$A$14,0)),Customers!U2=0),"",IF(ISNUMBER(Customers!U2),Customers!U2,IFERROR(VALUE(Customers!U2),""))) -> 698 | V2: =IF(OR(TRIM(Customers!V2&"")="",ISNUMBER(MATCH(TRIM(Customers!V2&""),Codes!$A$5:$A$14,0))),"",IF(ISNUMBER(Customers!V2),Customers!V2,IFERROR(VALUE(Customers!V2),"")))
A3: =Customers!A3 -> CL00002 | B3: =IF(OR(TRIM(Customers!B3&"")="",ISNUMBER(MATCH(TRIM(Customers!B3&""),Codes!$A$5:$A$14,0)),Customers!B3=0),"",IF(ISNUMBER(Customers!B3),Customers!B3,IFERROR(VALUE(Customers!B3),""))) -> 60 | C3: =IF(OR(TRIM(Customers!C3&"")="",ISNUMBER(MATCH(TRIM(Customers!C3&""),Codes!$A$5:$A$14,0))),"",TRIM(Customers!C3)) -> M | D3: =IF(OR(TRIM(Customers!D3&"")="",ISNUMBER(MATCH(TRIM(Customers!D3&""),Codes!$A$5:$A$14,0))),"",TRIM(Customers!D3)) -> Abruzzo | E3: =IF(OR(TRIM(Customers!E3&"")="",ISNUMBER(MATCH(TRIM(Customers!E3&""),Codes!$A$5:$A$14,0))),"",TRIM(Customers!E3)) -> Business owner | F3: =IF(OR(TRIM(Customers!F3&"")="",ISNUMBER(MATCH(TRIM(Customers!F3&""),Codes!$A$5:$A$14,0))),"",TRIM(Customers!F3)) -> Married | G3: =IF(OR(TRIM(Customers!G3&"")="",ISNUMBER(MATCH(TRIM(Customers!G3&""),Codes!$A$5:$A$14,0)),Customers!G3=-999),"",IF(ISNUMBER(Customers!G3),Customers!G3,IFERROR(VALUE(Customers!G3),""))) -> 117400 | H3: =IF(OR(TRIM(Customers!H3&"")="",ISNUMBER(MATCH(TRIM(Customers!H3&""),Codes!$A$5:$A$14,0))),"",IF(ISNUMBER(Customers!H3),Customers!H3,IFERROR(VALUE(Customers!H3),""))) -> 13 | I3: =IF(OR(TRIM(Customers!I3&"")="",ISNUMBER(MATCH(TRIM(Customers!I3&""),Codes!$A$5:$A$14,0)),Customers!I3=DATE(1970,1,1)),"",IF(ISNUMBER(Customers!I3),Customers!I3,IFERROR(DATEVALUE(Customers!I3),""))) -> 41314 | J3: =IF(OR(TRIM(Customers!J3&"")="",ISNUMBER(MATCH(TRIM(Customers!J3&""),Codes!$A$5:$A$14,0))),"",TRIM(Customers!J3)) -> Branch | K3: =IF(OR(TRIM(Customers!K3&"")="",ISNUMBER(MATCH(TRIM(Customers!K3&""),Codes!$A$5:$A$14,0))),"",IF(ISNUMBER(Customers!K3),Customers!K3,IFERROR(VALUE(Customers!K3),""))) -> 3 | L3: =IF(OR(TRIM(Customers!L3&"")="",ISNUMBER(MATCH(TRIM(Customers!L3&""),Codes!$A$5:$A$14,0))),"",IF(ISNUMBER(Customers!L3),Customers!L3,IFERROR(VALUE(Customers!L3),""))) -> 39402.14 | M3: =IF(OR(TRIM(Customers!M3&"")="",ISNUMBER(MATCH(TRIM(Customers!M3&""),Codes!$A$5:$A$14,0))),"",IF(ISNUMBER(Customers!M3),Customers!M3,IFERROR(VALUE(Customers!M3),""))) -> 124631.07 | N3: =IF(OR(TRIM(Customers!N3&"")="",ISNUMBER(MATCH(TRIM(Customers!N3&""),Codes!$A$5:$A$14,0)),Customers!N3=9999),"",IF(ISNUMBER(Customers!N3),Customers!N3,IFERROR(VALUE(Customers!N3),""))) -> 49 | O3: =IF(OR(TRIM(Customers!O3&"")="",ISNUMBER(MATCH(TRIM(Customers!O3&""),Codes!$A$5:$A$14,0))),"",IF(ISNUMBER(Customers!O3),Customers!O3,IFERROR(VALUE(Customers!O3),""))) -> 65.95 | P3: =IF(OR(TRIM(Customers!P3&"")="",ISNUMBER(MATCH(TRIM(Customers!P3&""),Codes!$A$5:$A$14,0))),"",IF(ISNUMBER(Customers!P3),Customers!P3,IFERROR(VALUE(Customers!P3),""))) -> 1 | Q3: =IF(OR(TRIM(Customers!Q3&"")="",ISNUMBER(MATCH(TRIM(Customers!Q3&""),Codes!$A$5:$A$14,0))),"",IF(ISNUMBER(Customers!Q3),Customers!Q3,IFERROR(VALUE(Customers!Q3),""))) -> 15000 | R3: =IF(OR(TRIM(Customers!R3&"")="",ISNUMBER(MATCH(TRIM(Customers!R3&""),Codes!$A$5:$A$14,0))),"",IF(ISNUMBER(Customers!R3),Customers!R3,IFERROR(VALUE(Customers!R3),""))) -> 3434.25 | S3: =IF(OR(TRIM(Customers!S3&"")="",ISNUMBER(MATCH(TRIM(Customers!S3&""),Codes!$A$5:$A$14,0))),"",IF(ISNUMBER(Customers!S3),Customers!S3,IFERROR(VALUE(Customers!S3),""))) -> 0 | T3: =IF(OR(TRIM(Customers!T3&"")="",ISNUMBER(MATCH(TRIM(Customers!T3&""),Codes!$A$5:$A$14,0))),"",IF(ISNUMBER(Customers!T3),Customers!T3,IFERROR(VALUE(Customers!T3),""))) -> 0 | U3: =IF(OR(TRIM(Customers!U3&"")="",ISNUMBER(MATCH(TRIM(Customers!U3&""),Codes!$A$5:$A$14,0)),Customers!U3=0),"",IF(ISNUMBER(Customers!U3),Customers!U3,IFERROR(VALUE(Customers!U3),""))) -> 700 | V3: =IF(OR(TRIM(Customers!V3&"")="",ISNUMBER(MATCH(TRIM(Customers!V3&""),Codes!$A$5:$A$14,0))),"",IF(ISNUMBER(Customers!V3),Customers!V3,IFERROR(VALUE(Customers!V3),"")))
A4: =Customers!A4 -> CL00003 | B4: =IF(OR(TRIM(Customers!B4&"")="",ISNUMBER(MATCH(TRIM(Customers!B4&""),Codes!$A$5:$A$14,0)),Customers!B4=0),"",IF(ISNUMBER(Customers!B4),Customers!B4,IFERROR(VALUE(Customers!B4),""))) -> 42 | C4: =IF(OR(TRIM(Customers!C4&"")="",ISNUMBER(MATCH(TRIM(Customers!C4&""),Codes!$A$5:$A$14,0))),"",TRIM(Customers!C4)) -> F | D4: =IF(OR(TRIM(Customers!D4&"")="",ISNUMBER(MATCH(TRIM(Customers!D4&""),Codes!$A$5:$A$14,0))),"",TRIM(Customers!D4)) -> Molise | E4: =IF(OR(TRIM(Customers!E4&"")="",ISNUMBER(MATCH(TRIM(Customers!E4&""),Codes!$A$5:$A$14,0))),"",TRIM(Customers!E4)) -> Business owner | F4: =IF(OR(TRIM(Customers!F4&"")="",ISNUMBER(MATCH(TRIM(Customers!F4&""),Codes!$A$5:$A$14,0))),"",TRIM(Customers!F4)) -> Married | G4: =IF(OR(TRIM(Customers!G4&"")="",ISNUMBER(MATCH(TRIM(Customers!G4&""),Codes!$A$5:$A$14,0)),Customers!G4=-999),"",IF(ISNUMBER(Customers!G4),Customers!G4,IFERROR(VALUE(Customers!G4),""))) -> 55600 | H4: =IF(OR(TRIM(Customers!H4&"")="",ISNUMBER(MATCH(TRIM(Customers!H4&""),Codes!$A$5:$A$14,0))),"",IF(ISNUMBER(Customers!H4),Customers!H4,IFERROR(VALUE(Customers!H4),""))) -> 11 | I4: =IF(OR(TRIM(Customers!I4&"")="",ISNUMBER(MATCH(TRIM(Customers!I4&""),Codes!$A$5:$A$14,0)),Customers!I4=DATE(1970,1,1)),"",IF(ISNUMBER(Customers!I4),Customers!I4,IFERROR(DATEVALUE(Customers!I4),""))) -> 41985 | J4: =IF(OR(TRIM(Customers!J4&"")="",ISNUMBER(MATCH(TRIM(Customers!J4&""),Codes!$A$5:$A$14,0))),"",TRIM(Customers!J4)) -> App | K4: =IF(OR(TRIM(Customers!K4&"")="",ISNUMBER(MATCH(TRIM(Customers!K4&""),Codes!$A$5:$A$14,0))),"",IF(ISNUMBER(Customers!K4),Customers!K4,IFERROR(VALUE(Customers!K4),""))) -> 2 | L4: =IF(OR(TRIM(Customers!L4&"")="",ISNUMBER(MATCH(TRIM(Customers!L4&""),Codes!$A$5:$A$14,0))),"",IF(ISNUMBER(Customers!L4),Customers!L4,IFERROR(VALUE(Customers!L4),""))) -> 2962.55 | M4: =IF(OR(TRIM(Customers!M4&"")="",ISNUMBER(MATCH(TRIM(Customers!M4&""),Codes!$A$5:$A$14,0))),"",IF(ISNUMBER(Customers!M4),Customers!M4,IFERROR(VALUE(Customers!M4),""))) -> 70371.89 | N4: =IF(OR(TRIM(Customers!N4&"")="",ISNUMBER(MATCH(TRIM(Customers!N4&""),Codes!$A$5:$A$14,0)),Customers!N4=9999),"",IF(ISNUMBER(Customers!N4),Customers!N4,IFERROR(VALUE(Customers!N4),""))) -> 33 | O4: =IF(OR(TRIM(Customers!O4&"")="",ISNUMBER(MATCH(TRIM(Customers!O4&""),Codes!$A$5:$A$14,0))),"",IF(ISNUMBER(Customers!O4),Customers!O4,IFERROR(VALUE(Customers!O4),""))) -> 85.29 | P4: =IF(OR(TRIM(Customers!P4&"")="",ISNUMBER(MATCH(TRIM(Customers!P4&""),Codes!$A$5:$A$14,0))),"",IF(ISNUMBER(Customers!P4),Customers!P4,IFERROR(VALUE(Customers!P4),""))) -> 1 | Q4: =IF(OR(TRIM(Customers!Q4&"")="",ISNUMBER(MATCH(TRIM(Customers!Q4&""),Codes!$A$5:$A$14,0))),"",IF(ISNUMBER(Customers!Q4),Customers!Q4,IFERROR(VALUE(Customers!Q4),""))) -> 11000 | R4: =IF(OR(TRIM(Customers!R4&"")="",ISNUMBER(MATCH(TRIM(Customers!R4&""),Codes!$A$5:$A$14,0))),"",IF(ISNUMBER(Customers!R4),Customers!R4,IFERROR(VALUE(Customers!R4),""))) -> 3647.56 | S4: =IF(OR(TRIM(Customers!S4&"")="",ISNUMBER(MATCH(TRIM(Customers!S4&""),Codes!$A$5:$A$14,0))),"",IF(ISNUMBER(Customers!S4),Customers!S4,IFERROR(VALUE(Customers!S4),""))) | T4: =IF(OR(TRIM(Customers!T4&"")="",ISNUMBER(MATCH(TRIM(Customers!T4&""),Codes!$A$5:$A$14,0))),"",IF(ISNUMBER(Customers!T4),Customers!T4,IFERROR(VALUE(Customers!T4),""))) | U4: =IF(OR(TRIM(Customers!U4&"")="",ISNUMBER(MATCH(TRIM(Customers!U4&""),Codes!$A$5:$A$14,0)),Customers!U4=0),"",IF(ISNUMBER(Customers!U4),Customers!U4,IFERROR(VALUE(Customers!U4),""))) -> 749 | V4: =IF(OR(TRIM(Customers!V4&"")="",ISNUMBER(MATCH(TRIM(Customers!V4&""),Codes!$A$5:$A$14,0))),"",IF(ISNUMBER(Customers!V4),Customers!V4,IFERROR(VALUE(Customers!V4),"")))
A5: =Customers!A5 -> CL00004 | B5: =IF(OR(TRIM(Customers!B5&"")="",ISNUMBER(MATCH(TRIM(Customers!B5&""),Codes!$A$5:$A$14,0)),Customers!B5=0),"",IF(ISNUMBER(Customers!B5),Customers!B5,IFERROR(VALUE(Customers!B5),""))) -> 44 | C5: =IF(OR(TRIM(Customers!C5&"")="",ISNUMBER(MATCH(TRIM(Customers!C5&""),Codes!$A$5:$A$14,0))),"",TRIM(Customers!C5)) -> F | D5: =IF(OR(TRIM(Customers!D5&"")="",ISNUMBER(MATCH(TRIM(Customers!D5&""),Codes!$A$5:$A$14,0))),"",TRIM(Customers!D5)) -> Umbria | E5: =IF(OR(TRIM(Customers!E5&"")="",ISNUMBER(MATCH(TRIM(Customers!E5&""),Codes!$A$5:$A$14,0))),"",TRIM(Customers!E5)) -> Employee | F5: =IF(OR(TRIM(Customers!F5&"")="",ISNUMBER(MATCH(TRIM(Customers!F5&""),Codes!$A$5:$A$14,0))),"",TRIM(Customers!F5)) -> Single | G5: =IF(OR(TRIM(Customers!G5&"")="",ISNUMBER(MATCH(TRIM(Customers!G5&""),Codes!$A$5:$A$14,0)),Customers!G5=-999),"",IF(ISNUMBER(Customers!G5),Customers!G5,IFERROR(VALUE(Customers!G5),""))) -> 30200 | H5: =IF(OR(TRIM(Customers!H5&"")="",ISNUMBER(MATCH(TRIM(Customers!H5&""),Codes!$A$5:$A$14,0))),"",IF(ISNUMBER(Customers!H5),Customers!H5,IFERROR(VALUE(Customers!H5),""))) -> 13 | I5: =IF(OR(TRIM(Customers!I5&"")="",ISNUMBER(MATCH(TRIM(Customers!I5&""),Codes!$A$5:$A$14,0)),Customers!I5=DATE(1970,1,1)),"",IF(ISNUMBER(Customers!I5),Customers!I5,IFERROR(DATEVALUE(Customers!I5),""))) -> 41353 | J5: =IF(OR(TRIM(Customers!J5&"")="",ISNUMBER(MATCH(TRIM(Customers!J5&""),Codes!$A$5:$A$14,0))),"",TRIM(Customers!J5)) -> App | K5: =IF(OR(TRIM(Customers!K5&"")="",ISNUMBER(MATCH(TRIM(Customers!K5&""),Codes!$A$5:$A$14,0))),"",IF(ISNUMBER(Customers!K5),Customers!K5,IFERROR(VALUE(Customers!K5),""))) -> 2 | L5: =IF(OR(TRIM(Customers!L5&"")="",ISNUMBER(MATCH(TRIM(Customers!L5&""),Codes!$A$5:$A$14,0))),"",IF(ISNUMBER(Customers!L5),Customers!L5,IFERROR(VALUE(Customers!L5),""))) -> 3055.07 | M5: =IF(OR(TRIM(Customers!M5&"")="",ISNUMBER(MATCH(TRIM(Customers!M5&""),Codes!$A$5:$A$14,0))),"",IF(ISNUMBER(Customers!M5),Customers!M5,IFERROR(VALUE(Customers!M5),""))) -> 31571.98 | N5: =IF(OR(TRIM(Customers!N5&"")="",ISNUMBER(MATCH(TRIM(Customers!N5&""),Codes!$A$5:$A$14,0)),Customers!N5=9999),"",IF(ISNUMBER(Customers!N5),Customers!N5,IFERROR(VALUE(Customers!N5),""))) -> 17 | O5: =IF(OR(TRIM(Customers!O5&"")="",ISNUMBER(MATCH(TRIM(Customers!O5&""),Codes!$A$5:$A$14,0))),"",IF(ISNUMBER(Customers!O5),Customers!O5,IFERROR(VALUE(Customers!O5),""))) -> 30.81 | P5: =IF(OR(TRIM(Customers!P5&"")="",ISNUMBER(MATCH(TRIM(Customers!P5&""),Codes!$A$5:$A$14,0))),"",IF(ISNUMBER(Customers!P5),Customers!P5,IFERROR(VALUE(Customers!P5),""))) -> 1 | Q5: =IF(OR(TRIM(Customers!Q5&"")="",ISNUMBER(MATCH(TRIM(Customers!Q5&""),Codes!$A$5:$A$14,0))),"",IF(ISNUMBER(Customers!Q5),Customers!Q5,IFERROR(VALUE(Customers!Q5),""))) -> 6000 | R5: =IF(OR(TRIM(Customers!R5&"")="",ISNUMBER(MATCH(TRIM(Customers!R5&""),Codes!$A$5:$A$14,0))),"",IF(ISNUMBER(Customers!R5),Customers!R5,IFERROR(VALUE(Customers!R5),""))) -> 2242.95 | S5: =IF(OR(TRIM(Customers!S5&"")="",ISNUMBER(MATCH(TRIM(Customers!S5&""),Codes!$A$5:$A$14,0))),"",IF(ISNUMBER(Customers!S5),Customers!S5,IFERROR(VALUE(Customers!S5),""))) -> 0 | T5: =IF(OR(TRIM(Customers!T5&"")="",ISNUMBER(MATCH(TRIM(Customers!T5&""),Codes!$A$5:$A$14,0))),"",IF(ISNUMBER(Customers!T5),Customers!T5,IFERROR(VALUE(Customers!T5),""))) -> 0 | U5: =IF(OR(TRIM(Customers!U5&"")="",ISNUMBER(MATCH(TRIM(Customers!U5&""),Codes!$A$5:$A$14,0)),Customers!U5=0),"",IF(ISNUMBER(Customers!U5),Customers!U5,IFERROR(VALUE(Customers!U5),""))) -> 601 | V5: =IF(OR(TRIM(Customers!V5&"")="",ISNUMBER(MATCH(TRIM(Customers!V5&""),Codes!$A$5:$A$14,0))),"",IF(ISNUMBER(Customers!V5),Customers!V5,IFERROR(VALUE(Customers!V5),""))) -> 0
A6: =Customers!A6 -> CL00005 | B6: =IF(OR(TRIM(Customers!B6&"")="",ISNUMBER(MATCH(TRIM(Customers!B6&""),Codes!$A$5:$A$14,0)),Customers!B6=0),"",IF(ISNUMBER(Customers!B6),Customers!B6,IFERROR(VALUE(Customers!B6),""))) -> 68 | C6: =IF(OR(TRIM(Customers!C6&"")="",ISNUMBER(MATCH(TRIM(Customers!C6&""),Codes!$A$5:$A$14,0))),"",TRIM(Customers!C6)) -> F | D6: =IF(OR(TRIM(Customers!D6&"")="",ISNUMBER(MATCH(TRIM(Customers!D6&""),Codes!$A$5:$A$14,0))),"",TRIM(Customers!D6)) -> Lombardia | E6: =IF(OR(TRIM(Customers!E6&"")="",ISNUMBER(MATCH(TRIM(Customers!E6&""),Codes!$A$5:$A$14,0))),"",TRIM(Customers!E6)) -> Retired | F6: =IF(OR(TRIM(Customers!F6&"")="",ISNUMBER(MATCH(TRIM(Customers!F6&""),Codes!$A$5:$A$14,0))),"",TRIM(Customers!F6)) -> Married | G6: =IF(OR(TRIM(Customers!G6&"")="",ISNUMBER(MATCH(TRIM(Customers!G6&""),Codes!$A$5:$A$14,0)),Customers!G6=-999),"",IF(ISNUMBER(Customers!G6),Customers!G6,IFERROR(VALUE(Customers!G6),""))) -> 21800 | H6: =IF(OR(TRIM(Customers!H6&"")="",ISNUMBER(MATCH(TRIM(Customers!H6&""),Codes!$A$5:$A$14,0))),"",IF(ISNUMBER(Customers!H6),Customers!H6,IFERROR(VALUE(Customers!H6),""))) -> 8 | I6: =IF(OR(TRIM(Customers!I6&"")="",ISNUMBER(MATCH(TRIM(Customers!I6&""),Codes!$A$5:$A$14,0)),Customers!I6=DATE(1970,1,1)),"",IF(ISNUMBER(Customers!I6),Customers!I6,IFERROR(DATEVALUE(Customers!I6),""))) -> 43047 | J6: =IF(OR(TRIM(Customers!J6&"")="",ISNUMBER(MATCH(TRIM(Customers!J6&""),Codes!$A$5:$A$14,0))),"",TRIM(Customers!J6)) -> Phone | K6: =IF(OR(TRIM(Customers!K6&"")="",ISNUMBER(MATCH(TRIM(Customers!K6&""),Codes!$A$5:$A$14,0))),"",IF(ISNUMBER(Customers!K6),Customers!K6,IFERROR(VALUE(Customers!K6),""))) -> 1 | L6: =IF(OR(TRIM(Customers!L6&"")="",ISNUMBER(MATCH(TRIM(Customers!L6&""),Codes!$A$5:$A$14,0))),"",IF(ISNUMBER(Customers!L6),Customers!L6,IFERROR(VALUE(Customers!L6),""))) -> 1554.39 | M6: =IF(OR(TRIM(Customers!M6&"")="",ISNUMBER(MATCH(TRIM(Customers!M6&""),Codes!$A$5:$A$14,0))),"",IF(ISNUMBER(Customers!M6),Customers!M6,IFERROR(VALUE(Customers!M6),""))) -> 27565.84 | N6: =IF(OR(TRIM(Customers!N6&"")="",ISNUMBER(MATCH(TRIM(Customers!N6&""),Codes!$A$5:$A$14,0)),Customers!N6=9999),"",IF(ISNUMBER(Customers!N6),Customers!N6,IFERROR(VALUE(Customers!N6),""))) -> 24 | O6: =IF(OR(TRIM(Customers!O6&"")="",ISNUMBER(MATCH(TRIM(Customers!O6&""),Codes!$A$5:$A$14,0))),"",IF(ISNUMBER(Customers!O6),Customers!O6,IFERROR(VALUE(Customers!O6),""))) -> 29.47 | P6: =IF(OR(TRIM(Customers!P6&"")="",ISNUMBER(MATCH(TRIM(Customers!P6&""),Codes!$A$5:$A$14,0))),"",IF(ISNUMBER(Customers!P6),Customers!P6,IFERROR(VALUE(Customers!P6),""))) -> 4 | Q6: =IF(OR(TRIM(Customers!Q6&"")="",ISNUMBER(MATCH(TRIM(Customers!Q6&""),Codes!$A$5:$A$14,0))),"",IF(ISNUMBER(Customers!Q6),Customers!Q6,IFERROR(VALUE(Customers!Q6),""))) -> 5000 | R6: =IF(OR(TRIM(Customers!R6&"")="",ISNUMBER(MATCH(TRIM(Customers!R6&""),Codes!$A$5:$A$14,0))),"",IF(ISNUMBER(Customers!R6),Customers!R6,IFERROR(VALUE(Customers!R6),""))) -> 1312.86 | S6: =IF(OR(TRIM(Customers!S6&"")="",ISNUMBER(MATCH(TRIM(Customers!S6&""),Codes!$A$5:$A$14,0))),"",IF(ISNUMBER(Customers!S6),Customers!S6,IFERROR(VALUE(Customers!S6),""))) | T6: =IF(OR(TRIM(Customers!T6&"")="",ISNUMBER(MATCH(TRIM(Customers!T6&""),Codes!$A$5:$A$14,0))),"",IF(ISNUMBER(Customers!T6),Customers!T6,IFERROR(VALUE(Customers!T6),""))) | U6: =IF(OR(TRIM(Customers!U6&"")="",ISNUMBER(MATCH(TRIM(Customers!U6&""),Codes!$A$5:$A$14,0)),Customers!U6=0),"",IF(ISNUMBER(Customers!U6),Customers!U6,IFERROR(VALUE(Customers!U6),""))) -> 568 | V6: =IF(OR(TRIM(Customers!V6&"")="",ISNUMBER(MATCH(TRIM(Customers!V6&""),Codes!$A$5:$A$14,0))),"",IF(ISNUMBER(Customers!V6),Customers!V6,IFERROR(VALUE(Customers!V6),""))) -> 1
